INFO 2025-08-04 10:51:50,643 autoreload 19580 5524 Watching for file changes with StatReloader
INFO 2025-08-04 10:52:03,263 basehttp 19580 4064 "GET / HTTP/1.1" 302 0
INFO 2025-08-04 10:52:03,427 basehttp 19580 4064 "GET /login/?next=/ HTTP/1.1" 200 13693
WARNING 2025-08-04 10:52:03,758 log 19580 4064 Not Found: /favicon.ico
WARNING 2025-08-04 10:52:03,759 basehttp 19580 4064 "GET /favicon.ico HTTP/1.1" 404 9327
INFO 2025-08-04 10:52:08,925 basehttp 19580 4064 "POST /login/?next=/ HTTP/1.1" 302 0
WARNING 2025-08-04 10:52:09,324 log 19580 21664 Forbidden (CSRF token from POST incorrect.): /login/
WARNING 2025-08-04 10:52:09,348 basehttp 19580 21664 "POST /login/?next=/ HTTP/1.1" 403 2503
ERROR 2025-08-04 10:52:09,641 log 19580 4064 Internal Server Error: /
Traceback (most recent call last):
  File "C:\Users\priya\OneDrive\Documents\IT\python\pd\django_emr\venv\Lib\site-packages\django\db\models\fields\related_descriptors.py", line 513, in __get__
    rel_obj = self.related.get_cached_value(instance)
              ^^^^^^^^^^^^^^^^^^^^^^^^^^^^^^^^^^^^^^^
  File "C:\Users\priya\OneDrive\Documents\IT\python\pd\django_emr\venv\Lib\site-packages\django\db\models\fields\mixins.py", line 37, in get_cached_value
    return instance._state.fields_cache[self.cache_name]
           ~~~~~~~~~~~~~~~~~~~~~~~~~~~~^^^^^^^^^^^^^^^^^
KeyError: 'doctor_profile'

During handling of the above exception, another exception occurred:

Traceback (most recent call last):
  File "C:\Users\priya\OneDrive\Documents\IT\python\pd\django_emr\venv\Lib\site-packages\django\db\backends\utils.py", line 105, in _execute
    return self.cursor.execute(sql, params)
           ^^^^^^^^^^^^^^^^^^^^^^^^^^^^^^^^
  File "C:\Users\priya\OneDrive\Documents\IT\python\pd\django_emr\venv\Lib\site-packages\django\db\backends\mysql\base.py", line 76, in execute
    return self.cursor.execute(query, args)
           ^^^^^^^^^^^^^^^^^^^^^^^^^^^^^^^^
  File "C:\Users\priya\OneDrive\Documents\IT\python\pd\django_emr\venv\Lib\site-packages\MySQLdb\cursors.py", line 179, in execute
    res = self._query(mogrified_query)
          ^^^^^^^^^^^^^^^^^^^^^^^^^^^^
  File "C:\Users\priya\OneDrive\Documents\IT\python\pd\django_emr\venv\Lib\site-packages\MySQLdb\cursors.py", line 330, in _query
    db.query(q)
  File "C:\Users\priya\OneDrive\Documents\IT\python\pd\django_emr\venv\Lib\site-packages\MySQLdb\connections.py", line 280, in query
    _mysql.connection.query(self, query)
MySQLdb.ProgrammingError: (1146, "Table 'emr_db.emr_app_doctor' doesn't exist")

The above exception was the direct cause of the following exception:

Traceback (most recent call last):
  File "C:\Users\priya\OneDrive\Documents\IT\python\pd\django_emr\venv\Lib\site-packages\django\core\handlers\exception.py", line 55, in inner
    response = get_response(request)
               ^^^^^^^^^^^^^^^^^^^^^
  File "C:\Users\priya\OneDrive\Documents\IT\python\pd\django_emr\venv\Lib\site-packages\django\core\handlers\base.py", line 197, in _get_response
    response = wrapped_callback(request, *callback_args, **callback_kwargs)
               ^^^^^^^^^^^^^^^^^^^^^^^^^^^^^^^^^^^^^^^^^^^^^^^^^^^^^^^^^^^^
  File "C:\Users\priya\OneDrive\Documents\IT\python\pd\django_emr\venv\Lib\site-packages\django\contrib\auth\decorators.py", line 59, in _view_wrapper
    return view_func(request, *args, **kwargs)
           ^^^^^^^^^^^^^^^^^^^^^^^^^^^^^^^^^^^
  File "C:\Users\priya\OneDrive\Documents\IT\python\pd\django_emr\emr_project\emr_app\views.py", line 95, in home
    if request.user.is_staff or is_doctor(request.user):
                                ^^^^^^^^^^^^^^^^^^^^^^^
  File "C:\Users\priya\OneDrive\Documents\IT\python\pd\django_emr\emr_project\emr_app\views.py", line 27, in is_doctor
    return hasattr(user, 'doctor_profile') and user.doctor_profile.is_active
           ^^^^^^^^^^^^^^^^^^^^^^^^^^^^^^^
  File "C:\Users\priya\OneDrive\Documents\IT\python\pd\django_emr\venv\Lib\site-packages\django\utils\functional.py", line 253, in inner
    return func(_wrapped, *args)
           ^^^^^^^^^^^^^^^^^^^^^
  File "C:\Users\priya\OneDrive\Documents\IT\python\pd\django_emr\venv\Lib\site-packages\django\db\models\fields\related_descriptors.py", line 520, in __get__
    rel_obj = self.get_queryset(instance=instance).get(**filter_args)
              ^^^^^^^^^^^^^^^^^^^^^^^^^^^^^^^^^^^^^^^^^^^^^^^^^^^^^^^
  File "C:\Users\priya\OneDrive\Documents\IT\python\pd\django_emr\venv\Lib\site-packages\django\db\models\query.py", line 629, in get
    num = len(clone)
          ^^^^^^^^^^
  File "C:\Users\priya\OneDrive\Documents\IT\python\pd\django_emr\venv\Lib\site-packages\django\db\models\query.py", line 366, in __len__
    self._fetch_all()
  File "C:\Users\priya\OneDrive\Documents\IT\python\pd\django_emr\venv\Lib\site-packages\django\db\models\query.py", line 1935, in _fetch_all
    self._result_cache = list(self._iterable_class(self))
                         ^^^^^^^^^^^^^^^^^^^^^^^^^^^^^^^^
  File "C:\Users\priya\OneDrive\Documents\IT\python\pd\django_emr\venv\Lib\site-packages\django\db\models\query.py", line 91, in __iter__
    results = compiler.execute_sql(
              ^^^^^^^^^^^^^^^^^^^^^
  File "C:\Users\priya\OneDrive\Documents\IT\python\pd\django_emr\venv\Lib\site-packages\django\db\models\sql\compiler.py", line 1622, in execute_sql
    cursor.execute(sql, params)
  File "C:\Users\priya\OneDrive\Documents\IT\python\pd\django_emr\venv\Lib\site-packages\django\db\backends\utils.py", line 122, in execute
    return super().execute(sql, params)
           ^^^^^^^^^^^^^^^^^^^^^^^^^^^^
  File "C:\Users\priya\OneDrive\Documents\IT\python\pd\django_emr\venv\Lib\site-packages\django\db\backends\utils.py", line 79, in execute
    return self._execute_with_wrappers(
           ^^^^^^^^^^^^^^^^^^^^^^^^^^^^
  File "C:\Users\priya\OneDrive\Documents\IT\python\pd\django_emr\venv\Lib\site-packages\django\db\backends\utils.py", line 92, in _execute_with_wrappers
    return executor(sql, params, many, context)
           ^^^^^^^^^^^^^^^^^^^^^^^^^^^^^^^^^^^^
  File "C:\Users\priya\OneDrive\Documents\IT\python\pd\django_emr\venv\Lib\site-packages\django\db\backends\utils.py", line 100, in _execute
    with self.db.wrap_database_errors:
         ^^^^^^^^^^^^^^^^^^^^^^^^^^^^
  File "C:\Users\priya\OneDrive\Documents\IT\python\pd\django_emr\venv\Lib\site-packages\django\db\utils.py", line 91, in __exit__
    raise dj_exc_value.with_traceback(traceback) from exc_value
  File "C:\Users\priya\OneDrive\Documents\IT\python\pd\django_emr\venv\Lib\site-packages\django\db\backends\utils.py", line 105, in _execute
    return self.cursor.execute(sql, params)
           ^^^^^^^^^^^^^^^^^^^^^^^^^^^^^^^^
  File "C:\Users\priya\OneDrive\Documents\IT\python\pd\django_emr\venv\Lib\site-packages\django\db\backends\mysql\base.py", line 76, in execute
    return self.cursor.execute(query, args)
           ^^^^^^^^^^^^^^^^^^^^^^^^^^^^^^^^
  File "C:\Users\priya\OneDrive\Documents\IT\python\pd\django_emr\venv\Lib\site-packages\MySQLdb\cursors.py", line 179, in execute
    res = self._query(mogrified_query)
          ^^^^^^^^^^^^^^^^^^^^^^^^^^^^
  File "C:\Users\priya\OneDrive\Documents\IT\python\pd\django_emr\venv\Lib\site-packages\MySQLdb\cursors.py", line 330, in _query
    db.query(q)
  File "C:\Users\priya\OneDrive\Documents\IT\python\pd\django_emr\venv\Lib\site-packages\MySQLdb\connections.py", line 280, in query
    _mysql.connection.query(self, query)
django.db.utils.ProgrammingError: (1146, "Table 'emr_db.emr_app_doctor' doesn't exist")
INFO 2025-08-04 10:52:09,665 basehttp 19580 4064 - Broken pipe from ('127.0.0.1', 62900)
INFO 2025-08-04 10:52:13,669 basehttp 19580 21664 "GET /login/?next=/ HTTP/1.1" 200 14192
ERROR 2025-08-04 10:52:18,184 log 19580 21664 Internal Server Error: /
Traceback (most recent call last):
  File "C:\Users\priya\OneDrive\Documents\IT\python\pd\django_emr\venv\Lib\site-packages\django\db\models\fields\related_descriptors.py", line 513, in __get__
    rel_obj = self.related.get_cached_value(instance)
              ^^^^^^^^^^^^^^^^^^^^^^^^^^^^^^^^^^^^^^^
  File "C:\Users\priya\OneDrive\Documents\IT\python\pd\django_emr\venv\Lib\site-packages\django\db\models\fields\mixins.py", line 37, in get_cached_value
    return instance._state.fields_cache[self.cache_name]
           ~~~~~~~~~~~~~~~~~~~~~~~~~~~~^^^^^^^^^^^^^^^^^
KeyError: 'doctor_profile'

During handling of the above exception, another exception occurred:

Traceback (most recent call last):
  File "C:\Users\priya\OneDrive\Documents\IT\python\pd\django_emr\venv\Lib\site-packages\django\db\backends\utils.py", line 105, in _execute
    return self.cursor.execute(sql, params)
           ^^^^^^^^^^^^^^^^^^^^^^^^^^^^^^^^
  File "C:\Users\priya\OneDrive\Documents\IT\python\pd\django_emr\venv\Lib\site-packages\django\db\backends\mysql\base.py", line 76, in execute
    return self.cursor.execute(query, args)
           ^^^^^^^^^^^^^^^^^^^^^^^^^^^^^^^^
  File "C:\Users\priya\OneDrive\Documents\IT\python\pd\django_emr\venv\Lib\site-packages\MySQLdb\cursors.py", line 179, in execute
    res = self._query(mogrified_query)
          ^^^^^^^^^^^^^^^^^^^^^^^^^^^^
  File "C:\Users\priya\OneDrive\Documents\IT\python\pd\django_emr\venv\Lib\site-packages\MySQLdb\cursors.py", line 330, in _query
    db.query(q)
  File "C:\Users\priya\OneDrive\Documents\IT\python\pd\django_emr\venv\Lib\site-packages\MySQLdb\connections.py", line 280, in query
    _mysql.connection.query(self, query)
MySQLdb.ProgrammingError: (1146, "Table 'emr_db.emr_app_doctor' doesn't exist")

The above exception was the direct cause of the following exception:

Traceback (most recent call last):
  File "C:\Users\priya\OneDrive\Documents\IT\python\pd\django_emr\venv\Lib\site-packages\django\core\handlers\exception.py", line 55, in inner
    response = get_response(request)
               ^^^^^^^^^^^^^^^^^^^^^
  File "C:\Users\priya\OneDrive\Documents\IT\python\pd\django_emr\venv\Lib\site-packages\django\core\handlers\base.py", line 197, in _get_response
    response = wrapped_callback(request, *callback_args, **callback_kwargs)
               ^^^^^^^^^^^^^^^^^^^^^^^^^^^^^^^^^^^^^^^^^^^^^^^^^^^^^^^^^^^^
  File "C:\Users\priya\OneDrive\Documents\IT\python\pd\django_emr\venv\Lib\site-packages\django\contrib\auth\decorators.py", line 59, in _view_wrapper
    return view_func(request, *args, **kwargs)
           ^^^^^^^^^^^^^^^^^^^^^^^^^^^^^^^^^^^
  File "C:\Users\priya\OneDrive\Documents\IT\python\pd\django_emr\emr_project\emr_app\views.py", line 95, in home
    if request.user.is_staff or is_doctor(request.user):
                                ^^^^^^^^^^^^^^^^^^^^^^^
  File "C:\Users\priya\OneDrive\Documents\IT\python\pd\django_emr\emr_project\emr_app\views.py", line 27, in is_doctor
    return hasattr(user, 'doctor_profile') and user.doctor_profile.is_active
           ^^^^^^^^^^^^^^^^^^^^^^^^^^^^^^^
  File "C:\Users\priya\OneDrive\Documents\IT\python\pd\django_emr\venv\Lib\site-packages\django\utils\functional.py", line 253, in inner
    return func(_wrapped, *args)
           ^^^^^^^^^^^^^^^^^^^^^
  File "C:\Users\priya\OneDrive\Documents\IT\python\pd\django_emr\venv\Lib\site-packages\django\db\models\fields\related_descriptors.py", line 520, in __get__
    rel_obj = self.get_queryset(instance=instance).get(**filter_args)
              ^^^^^^^^^^^^^^^^^^^^^^^^^^^^^^^^^^^^^^^^^^^^^^^^^^^^^^^
  File "C:\Users\priya\OneDrive\Documents\IT\python\pd\django_emr\venv\Lib\site-packages\django\db\models\query.py", line 629, in get
    num = len(clone)
          ^^^^^^^^^^
  File "C:\Users\priya\OneDrive\Documents\IT\python\pd\django_emr\venv\Lib\site-packages\django\db\models\query.py", line 366, in __len__
    self._fetch_all()
  File "C:\Users\priya\OneDrive\Documents\IT\python\pd\django_emr\venv\Lib\site-packages\django\db\models\query.py", line 1935, in _fetch_all
    self._result_cache = list(self._iterable_class(self))
                         ^^^^^^^^^^^^^^^^^^^^^^^^^^^^^^^^
  File "C:\Users\priya\OneDrive\Documents\IT\python\pd\django_emr\venv\Lib\site-packages\django\db\models\query.py", line 91, in __iter__
    results = compiler.execute_sql(
              ^^^^^^^^^^^^^^^^^^^^^
  File "C:\Users\priya\OneDrive\Documents\IT\python\pd\django_emr\venv\Lib\site-packages\django\db\models\sql\compiler.py", line 1622, in execute_sql
    cursor.execute(sql, params)
  File "C:\Users\priya\OneDrive\Documents\IT\python\pd\django_emr\venv\Lib\site-packages\django\db\backends\utils.py", line 122, in execute
    return super().execute(sql, params)
           ^^^^^^^^^^^^^^^^^^^^^^^^^^^^
  File "C:\Users\priya\OneDrive\Documents\IT\python\pd\django_emr\venv\Lib\site-packages\django\db\backends\utils.py", line 79, in execute
    return self._execute_with_wrappers(
           ^^^^^^^^^^^^^^^^^^^^^^^^^^^^
  File "C:\Users\priya\OneDrive\Documents\IT\python\pd\django_emr\venv\Lib\site-packages\django\db\backends\utils.py", line 92, in _execute_with_wrappers
    return executor(sql, params, many, context)
           ^^^^^^^^^^^^^^^^^^^^^^^^^^^^^^^^^^^^
  File "C:\Users\priya\OneDrive\Documents\IT\python\pd\django_emr\venv\Lib\site-packages\django\db\backends\utils.py", line 100, in _execute
    with self.db.wrap_database_errors:
         ^^^^^^^^^^^^^^^^^^^^^^^^^^^^
  File "C:\Users\priya\OneDrive\Documents\IT\python\pd\django_emr\venv\Lib\site-packages\django\db\utils.py", line 91, in __exit__
    raise dj_exc_value.with_traceback(traceback) from exc_value
  File "C:\Users\priya\OneDrive\Documents\IT\python\pd\django_emr\venv\Lib\site-packages\django\db\backends\utils.py", line 105, in _execute
    return self.cursor.execute(sql, params)
           ^^^^^^^^^^^^^^^^^^^^^^^^^^^^^^^^
  File "C:\Users\priya\OneDrive\Documents\IT\python\pd\django_emr\venv\Lib\site-packages\django\db\backends\mysql\base.py", line 76, in execute
    return self.cursor.execute(query, args)
           ^^^^^^^^^^^^^^^^^^^^^^^^^^^^^^^^
  File "C:\Users\priya\OneDrive\Documents\IT\python\pd\django_emr\venv\Lib\site-packages\MySQLdb\cursors.py", line 179, in execute
    res = self._query(mogrified_query)
          ^^^^^^^^^^^^^^^^^^^^^^^^^^^^
  File "C:\Users\priya\OneDrive\Documents\IT\python\pd\django_emr\venv\Lib\site-packages\MySQLdb\cursors.py", line 330, in _query
    db.query(q)
  File "C:\Users\priya\OneDrive\Documents\IT\python\pd\django_emr\venv\Lib\site-packages\MySQLdb\connections.py", line 280, in query
    _mysql.connection.query(self, query)
django.db.utils.ProgrammingError: (1146, "Table 'emr_db.emr_app_doctor' doesn't exist")
ERROR 2025-08-04 10:52:18,193 basehttp 19580 21664 "GET / HTTP/1.1" 500 195552
INFO 2025-08-04 10:52:21,593 basehttp 19580 21664 "GET /login/?next=/ HTTP/1.1" 200 14192
ERROR 2025-08-04 10:52:23,446 log 19580 21664 Internal Server Error: /patients/
Traceback (most recent call last):
  File "C:\Users\priya\OneDrive\Documents\IT\python\pd\django_emr\venv\Lib\site-packages\django\db\models\fields\related_descriptors.py", line 513, in __get__
    rel_obj = self.related.get_cached_value(instance)
              ^^^^^^^^^^^^^^^^^^^^^^^^^^^^^^^^^^^^^^^
  File "C:\Users\priya\OneDrive\Documents\IT\python\pd\django_emr\venv\Lib\site-packages\django\db\models\fields\mixins.py", line 37, in get_cached_value
    return instance._state.fields_cache[self.cache_name]
           ~~~~~~~~~~~~~~~~~~~~~~~~~~~~^^^^^^^^^^^^^^^^^
KeyError: 'doctor_profile'

During handling of the above exception, another exception occurred:

Traceback (most recent call last):
  File "C:\Users\priya\OneDrive\Documents\IT\python\pd\django_emr\venv\Lib\site-packages\django\db\backends\utils.py", line 105, in _execute
    return self.cursor.execute(sql, params)
           ^^^^^^^^^^^^^^^^^^^^^^^^^^^^^^^^
  File "C:\Users\priya\OneDrive\Documents\IT\python\pd\django_emr\venv\Lib\site-packages\django\db\backends\mysql\base.py", line 76, in execute
    return self.cursor.execute(query, args)
           ^^^^^^^^^^^^^^^^^^^^^^^^^^^^^^^^
  File "C:\Users\priya\OneDrive\Documents\IT\python\pd\django_emr\venv\Lib\site-packages\MySQLdb\cursors.py", line 179, in execute
    res = self._query(mogrified_query)
          ^^^^^^^^^^^^^^^^^^^^^^^^^^^^
  File "C:\Users\priya\OneDrive\Documents\IT\python\pd\django_emr\venv\Lib\site-packages\MySQLdb\cursors.py", line 330, in _query
    db.query(q)
  File "C:\Users\priya\OneDrive\Documents\IT\python\pd\django_emr\venv\Lib\site-packages\MySQLdb\connections.py", line 280, in query
    _mysql.connection.query(self, query)
MySQLdb.ProgrammingError: (1146, "Table 'emr_db.emr_app_doctor' doesn't exist")

The above exception was the direct cause of the following exception:

Traceback (most recent call last):
  File "C:\Users\priya\OneDrive\Documents\IT\python\pd\django_emr\venv\Lib\site-packages\django\core\handlers\exception.py", line 55, in inner
    response = get_response(request)
               ^^^^^^^^^^^^^^^^^^^^^
  File "C:\Users\priya\OneDrive\Documents\IT\python\pd\django_emr\venv\Lib\site-packages\django\core\handlers\base.py", line 197, in _get_response
    response = wrapped_callback(request, *callback_args, **callback_kwargs)
               ^^^^^^^^^^^^^^^^^^^^^^^^^^^^^^^^^^^^^^^^^^^^^^^^^^^^^^^^^^^^
  File "C:\Users\priya\OneDrive\Documents\IT\python\pd\django_emr\venv\Lib\site-packages\django\contrib\auth\decorators.py", line 59, in _view_wrapper
    return view_func(request, *args, **kwargs)
           ^^^^^^^^^^^^^^^^^^^^^^^^^^^^^^^^^^^
  File "C:\Users\priya\OneDrive\Documents\IT\python\pd\django_emr\emr_project\emr_app\views.py", line 164, in patient_list
    if not (request.user.is_staff or is_doctor(request.user)):
                                     ^^^^^^^^^^^^^^^^^^^^^^^
  File "C:\Users\priya\OneDrive\Documents\IT\python\pd\django_emr\emr_project\emr_app\views.py", line 27, in is_doctor
    return hasattr(user, 'doctor_profile') and user.doctor_profile.is_active
           ^^^^^^^^^^^^^^^^^^^^^^^^^^^^^^^
  File "C:\Users\priya\OneDrive\Documents\IT\python\pd\django_emr\venv\Lib\site-packages\django\utils\functional.py", line 253, in inner
    return func(_wrapped, *args)
           ^^^^^^^^^^^^^^^^^^^^^
  File "C:\Users\priya\OneDrive\Documents\IT\python\pd\django_emr\venv\Lib\site-packages\django\db\models\fields\related_descriptors.py", line 520, in __get__
    rel_obj = self.get_queryset(instance=instance).get(**filter_args)
              ^^^^^^^^^^^^^^^^^^^^^^^^^^^^^^^^^^^^^^^^^^^^^^^^^^^^^^^
  File "C:\Users\priya\OneDrive\Documents\IT\python\pd\django_emr\venv\Lib\site-packages\django\db\models\query.py", line 629, in get
    num = len(clone)
          ^^^^^^^^^^
  File "C:\Users\priya\OneDrive\Documents\IT\python\pd\django_emr\venv\Lib\site-packages\django\db\models\query.py", line 366, in __len__
    self._fetch_all()
  File "C:\Users\priya\OneDrive\Documents\IT\python\pd\django_emr\venv\Lib\site-packages\django\db\models\query.py", line 1935, in _fetch_all
    self._result_cache = list(self._iterable_class(self))
                         ^^^^^^^^^^^^^^^^^^^^^^^^^^^^^^^^
  File "C:\Users\priya\OneDrive\Documents\IT\python\pd\django_emr\venv\Lib\site-packages\django\db\models\query.py", line 91, in __iter__
    results = compiler.execute_sql(
              ^^^^^^^^^^^^^^^^^^^^^
  File "C:\Users\priya\OneDrive\Documents\IT\python\pd\django_emr\venv\Lib\site-packages\django\db\models\sql\compiler.py", line 1622, in execute_sql
    cursor.execute(sql, params)
  File "C:\Users\priya\OneDrive\Documents\IT\python\pd\django_emr\venv\Lib\site-packages\django\db\backends\utils.py", line 122, in execute
    return super().execute(sql, params)
           ^^^^^^^^^^^^^^^^^^^^^^^^^^^^
  File "C:\Users\priya\OneDrive\Documents\IT\python\pd\django_emr\venv\Lib\site-packages\django\db\backends\utils.py", line 79, in execute
    return self._execute_with_wrappers(
           ^^^^^^^^^^^^^^^^^^^^^^^^^^^^
  File "C:\Users\priya\OneDrive\Documents\IT\python\pd\django_emr\venv\Lib\site-packages\django\db\backends\utils.py", line 92, in _execute_with_wrappers
    return executor(sql, params, many, context)
           ^^^^^^^^^^^^^^^^^^^^^^^^^^^^^^^^^^^^
  File "C:\Users\priya\OneDrive\Documents\IT\python\pd\django_emr\venv\Lib\site-packages\django\db\backends\utils.py", line 100, in _execute
    with self.db.wrap_database_errors:
         ^^^^^^^^^^^^^^^^^^^^^^^^^^^^
  File "C:\Users\priya\OneDrive\Documents\IT\python\pd\django_emr\venv\Lib\site-packages\django\db\utils.py", line 91, in __exit__
    raise dj_exc_value.with_traceback(traceback) from exc_value
  File "C:\Users\priya\OneDrive\Documents\IT\python\pd\django_emr\venv\Lib\site-packages\django\db\backends\utils.py", line 105, in _execute
    return self.cursor.execute(sql, params)
           ^^^^^^^^^^^^^^^^^^^^^^^^^^^^^^^^
  File "C:\Users\priya\OneDrive\Documents\IT\python\pd\django_emr\venv\Lib\site-packages\django\db\backends\mysql\base.py", line 76, in execute
    return self.cursor.execute(query, args)
           ^^^^^^^^^^^^^^^^^^^^^^^^^^^^^^^^
  File "C:\Users\priya\OneDrive\Documents\IT\python\pd\django_emr\venv\Lib\site-packages\MySQLdb\cursors.py", line 179, in execute
    res = self._query(mogrified_query)
          ^^^^^^^^^^^^^^^^^^^^^^^^^^^^
  File "C:\Users\priya\OneDrive\Documents\IT\python\pd\django_emr\venv\Lib\site-packages\MySQLdb\cursors.py", line 330, in _query
    db.query(q)
  File "C:\Users\priya\OneDrive\Documents\IT\python\pd\django_emr\venv\Lib\site-packages\MySQLdb\connections.py", line 280, in query
    _mysql.connection.query(self, query)
django.db.utils.ProgrammingError: (1146, "Table 'emr_db.emr_app_doctor' doesn't exist")
ERROR 2025-08-04 10:52:23,454 basehttp 19580 21664 "GET /patients/ HTTP/1.1" 500 195921
INFO 2025-08-04 10:52:25,208 basehttp 19580 21664 "GET /login/?next=/ HTTP/1.1" 200 14192
INFO 2025-08-04 11:04:38,651 autoreload 16836 14192 Watching for file changes with StatReloader
ERROR 2025-08-04 11:04:48,738 log 16836 18164 Internal Server Error: /
Traceback (most recent call last):
  File "C:\Users\priya\OneDrive\Documents\IT\python\pd\django_emr\venv\Lib\site-packages\django\db\models\fields\related_descriptors.py", line 513, in __get__
    rel_obj = self.related.get_cached_value(instance)
              ^^^^^^^^^^^^^^^^^^^^^^^^^^^^^^^^^^^^^^^
  File "C:\Users\priya\OneDrive\Documents\IT\python\pd\django_emr\venv\Lib\site-packages\django\db\models\fields\mixins.py", line 37, in get_cached_value
    return instance._state.fields_cache[self.cache_name]
           ~~~~~~~~~~~~~~~~~~~~~~~~~~~~^^^^^^^^^^^^^^^^^
KeyError: 'doctor_profile'

During handling of the above exception, another exception occurred:

Traceback (most recent call last):
  File "C:\Users\priya\OneDrive\Documents\IT\python\pd\django_emr\venv\Lib\site-packages\django\db\backends\utils.py", line 105, in _execute
    return self.cursor.execute(sql, params)
           ^^^^^^^^^^^^^^^^^^^^^^^^^^^^^^^^
  File "C:\Users\priya\OneDrive\Documents\IT\python\pd\django_emr\venv\Lib\site-packages\django\db\backends\mysql\base.py", line 76, in execute
    return self.cursor.execute(query, args)
           ^^^^^^^^^^^^^^^^^^^^^^^^^^^^^^^^
  File "C:\Users\priya\OneDrive\Documents\IT\python\pd\django_emr\venv\Lib\site-packages\MySQLdb\cursors.py", line 179, in execute
    res = self._query(mogrified_query)
          ^^^^^^^^^^^^^^^^^^^^^^^^^^^^
  File "C:\Users\priya\OneDrive\Documents\IT\python\pd\django_emr\venv\Lib\site-packages\MySQLdb\cursors.py", line 330, in _query
    db.query(q)
  File "C:\Users\priya\OneDrive\Documents\IT\python\pd\django_emr\venv\Lib\site-packages\MySQLdb\connections.py", line 280, in query
    _mysql.connection.query(self, query)
MySQLdb.ProgrammingError: (1146, "Table 'emr_db.emr_app_doctor' doesn't exist")

The above exception was the direct cause of the following exception:

Traceback (most recent call last):
  File "C:\Users\priya\OneDrive\Documents\IT\python\pd\django_emr\venv\Lib\site-packages\django\core\handlers\exception.py", line 55, in inner
    response = get_response(request)
               ^^^^^^^^^^^^^^^^^^^^^
  File "C:\Users\priya\OneDrive\Documents\IT\python\pd\django_emr\venv\Lib\site-packages\django\core\handlers\base.py", line 197, in _get_response
    response = wrapped_callback(request, *callback_args, **callback_kwargs)
               ^^^^^^^^^^^^^^^^^^^^^^^^^^^^^^^^^^^^^^^^^^^^^^^^^^^^^^^^^^^^
  File "C:\Users\priya\OneDrive\Documents\IT\python\pd\django_emr\venv\Lib\site-packages\django\contrib\auth\decorators.py", line 59, in _view_wrapper
    return view_func(request, *args, **kwargs)
           ^^^^^^^^^^^^^^^^^^^^^^^^^^^^^^^^^^^
  File "C:\Users\priya\OneDrive\Documents\IT\python\pd\django_emr\emr_project\emr_app\views.py", line 95, in home
    if request.user.is_staff or is_doctor(request.user):
                                ^^^^^^^^^^^^^^^^^^^^^^^
  File "C:\Users\priya\OneDrive\Documents\IT\python\pd\django_emr\emr_project\emr_app\views.py", line 27, in is_doctor
    return hasattr(user, 'doctor_profile') and user.doctor_profile.is_active
           ^^^^^^^^^^^^^^^^^^^^^^^^^^^^^^^
  File "C:\Users\priya\OneDrive\Documents\IT\python\pd\django_emr\venv\Lib\site-packages\django\utils\functional.py", line 253, in inner
    return func(_wrapped, *args)
           ^^^^^^^^^^^^^^^^^^^^^
  File "C:\Users\priya\OneDrive\Documents\IT\python\pd\django_emr\venv\Lib\site-packages\django\db\models\fields\related_descriptors.py", line 520, in __get__
    rel_obj = self.get_queryset(instance=instance).get(**filter_args)
              ^^^^^^^^^^^^^^^^^^^^^^^^^^^^^^^^^^^^^^^^^^^^^^^^^^^^^^^
  File "C:\Users\priya\OneDrive\Documents\IT\python\pd\django_emr\venv\Lib\site-packages\django\db\models\query.py", line 629, in get
    num = len(clone)
          ^^^^^^^^^^
  File "C:\Users\priya\OneDrive\Documents\IT\python\pd\django_emr\venv\Lib\site-packages\django\db\models\query.py", line 366, in __len__
    self._fetch_all()
  File "C:\Users\priya\OneDrive\Documents\IT\python\pd\django_emr\venv\Lib\site-packages\django\db\models\query.py", line 1935, in _fetch_all
    self._result_cache = list(self._iterable_class(self))
                         ^^^^^^^^^^^^^^^^^^^^^^^^^^^^^^^^
  File "C:\Users\priya\OneDrive\Documents\IT\python\pd\django_emr\venv\Lib\site-packages\django\db\models\query.py", line 91, in __iter__
    results = compiler.execute_sql(
              ^^^^^^^^^^^^^^^^^^^^^
  File "C:\Users\priya\OneDrive\Documents\IT\python\pd\django_emr\venv\Lib\site-packages\django\db\models\sql\compiler.py", line 1622, in execute_sql
    cursor.execute(sql, params)
  File "C:\Users\priya\OneDrive\Documents\IT\python\pd\django_emr\venv\Lib\site-packages\django\db\backends\utils.py", line 122, in execute
    return super().execute(sql, params)
           ^^^^^^^^^^^^^^^^^^^^^^^^^^^^
  File "C:\Users\priya\OneDrive\Documents\IT\python\pd\django_emr\venv\Lib\site-packages\django\db\backends\utils.py", line 79, in execute
    return self._execute_with_wrappers(
           ^^^^^^^^^^^^^^^^^^^^^^^^^^^^
  File "C:\Users\priya\OneDrive\Documents\IT\python\pd\django_emr\venv\Lib\site-packages\django\db\backends\utils.py", line 92, in _execute_with_wrappers
    return executor(sql, params, many, context)
           ^^^^^^^^^^^^^^^^^^^^^^^^^^^^^^^^^^^^
  File "C:\Users\priya\OneDrive\Documents\IT\python\pd\django_emr\venv\Lib\site-packages\django\db\backends\utils.py", line 100, in _execute
    with self.db.wrap_database_errors:
         ^^^^^^^^^^^^^^^^^^^^^^^^^^^^
  File "C:\Users\priya\OneDrive\Documents\IT\python\pd\django_emr\venv\Lib\site-packages\django\db\utils.py", line 91, in __exit__
    raise dj_exc_value.with_traceback(traceback) from exc_value
  File "C:\Users\priya\OneDrive\Documents\IT\python\pd\django_emr\venv\Lib\site-packages\django\db\backends\utils.py", line 105, in _execute
    return self.cursor.execute(sql, params)
           ^^^^^^^^^^^^^^^^^^^^^^^^^^^^^^^^
  File "C:\Users\priya\OneDrive\Documents\IT\python\pd\django_emr\venv\Lib\site-packages\django\db\backends\mysql\base.py", line 76, in execute
    return self.cursor.execute(query, args)
           ^^^^^^^^^^^^^^^^^^^^^^^^^^^^^^^^
  File "C:\Users\priya\OneDrive\Documents\IT\python\pd\django_emr\venv\Lib\site-packages\MySQLdb\cursors.py", line 179, in execute
    res = self._query(mogrified_query)
          ^^^^^^^^^^^^^^^^^^^^^^^^^^^^
  File "C:\Users\priya\OneDrive\Documents\IT\python\pd\django_emr\venv\Lib\site-packages\MySQLdb\cursors.py", line 330, in _query
    db.query(q)
  File "C:\Users\priya\OneDrive\Documents\IT\python\pd\django_emr\venv\Lib\site-packages\MySQLdb\connections.py", line 280, in query
    _mysql.connection.query(self, query)
django.db.utils.ProgrammingError: (1146, "Table 'emr_db.emr_app_doctor' doesn't exist")
ERROR 2025-08-04 11:04:48,764 basehttp 16836 18164 "GET / HTTP/1.1" 500 195388
INFO 2025-08-04 11:11:12,290 autoreload 15348 21356 Watching for file changes with StatReloader
ERROR 2025-08-04 11:11:23,298 log 15348 19628 Internal Server Error: /
Traceback (most recent call last):
  File "C:\Users\priya\OneDrive\Documents\IT\python\pd\django_emr\venv\Lib\site-packages\django\db\models\fields\related_descriptors.py", line 513, in __get__
    rel_obj = self.related.get_cached_value(instance)
              ^^^^^^^^^^^^^^^^^^^^^^^^^^^^^^^^^^^^^^^
  File "C:\Users\priya\OneDrive\Documents\IT\python\pd\django_emr\venv\Lib\site-packages\django\db\models\fields\mixins.py", line 37, in get_cached_value
    return instance._state.fields_cache[self.cache_name]
           ~~~~~~~~~~~~~~~~~~~~~~~~~~~~^^^^^^^^^^^^^^^^^
KeyError: 'doctor_profile'

During handling of the above exception, another exception occurred:

Traceback (most recent call last):
  File "C:\Users\priya\OneDrive\Documents\IT\python\pd\django_emr\venv\Lib\site-packages\django\db\backends\utils.py", line 105, in _execute
    return self.cursor.execute(sql, params)
           ^^^^^^^^^^^^^^^^^^^^^^^^^^^^^^^^
  File "C:\Users\priya\OneDrive\Documents\IT\python\pd\django_emr\venv\Lib\site-packages\django\db\backends\mysql\base.py", line 76, in execute
    return self.cursor.execute(query, args)
           ^^^^^^^^^^^^^^^^^^^^^^^^^^^^^^^^
  File "C:\Users\priya\OneDrive\Documents\IT\python\pd\django_emr\venv\Lib\site-packages\MySQLdb\cursors.py", line 179, in execute
    res = self._query(mogrified_query)
          ^^^^^^^^^^^^^^^^^^^^^^^^^^^^
  File "C:\Users\priya\OneDrive\Documents\IT\python\pd\django_emr\venv\Lib\site-packages\MySQLdb\cursors.py", line 330, in _query
    db.query(q)
  File "C:\Users\priya\OneDrive\Documents\IT\python\pd\django_emr\venv\Lib\site-packages\MySQLdb\connections.py", line 280, in query
    _mysql.connection.query(self, query)
MySQLdb.ProgrammingError: (1146, "Table 'emr_db.emr_app_doctor' doesn't exist")

The above exception was the direct cause of the following exception:

Traceback (most recent call last):
  File "C:\Users\priya\OneDrive\Documents\IT\python\pd\django_emr\venv\Lib\site-packages\django\core\handlers\exception.py", line 55, in inner
    response = get_response(request)
               ^^^^^^^^^^^^^^^^^^^^^
  File "C:\Users\priya\OneDrive\Documents\IT\python\pd\django_emr\venv\Lib\site-packages\django\core\handlers\base.py", line 197, in _get_response
    response = wrapped_callback(request, *callback_args, **callback_kwargs)
               ^^^^^^^^^^^^^^^^^^^^^^^^^^^^^^^^^^^^^^^^^^^^^^^^^^^^^^^^^^^^
  File "C:\Users\priya\OneDrive\Documents\IT\python\pd\django_emr\venv\Lib\site-packages\django\contrib\auth\decorators.py", line 59, in _view_wrapper
    return view_func(request, *args, **kwargs)
           ^^^^^^^^^^^^^^^^^^^^^^^^^^^^^^^^^^^
  File "C:\Users\priya\OneDrive\Documents\IT\python\pd\django_emr\emr_project\emr_app\views.py", line 95, in home
    if request.user.is_staff or is_doctor(request.user):
                                ^^^^^^^^^^^^^^^^^^^^^^^
  File "C:\Users\priya\OneDrive\Documents\IT\python\pd\django_emr\emr_project\emr_app\views.py", line 27, in is_doctor
    return hasattr(user, 'doctor_profile') and user.doctor_profile.is_active
           ^^^^^^^^^^^^^^^^^^^^^^^^^^^^^^^
  File "C:\Users\priya\OneDrive\Documents\IT\python\pd\django_emr\venv\Lib\site-packages\django\utils\functional.py", line 253, in inner
    return func(_wrapped, *args)
           ^^^^^^^^^^^^^^^^^^^^^
  File "C:\Users\priya\OneDrive\Documents\IT\python\pd\django_emr\venv\Lib\site-packages\django\db\models\fields\related_descriptors.py", line 520, in __get__
    rel_obj = self.get_queryset(instance=instance).get(**filter_args)
              ^^^^^^^^^^^^^^^^^^^^^^^^^^^^^^^^^^^^^^^^^^^^^^^^^^^^^^^
  File "C:\Users\priya\OneDrive\Documents\IT\python\pd\django_emr\venv\Lib\site-packages\django\db\models\query.py", line 629, in get
    num = len(clone)
          ^^^^^^^^^^
  File "C:\Users\priya\OneDrive\Documents\IT\python\pd\django_emr\venv\Lib\site-packages\django\db\models\query.py", line 366, in __len__
    self._fetch_all()
  File "C:\Users\priya\OneDrive\Documents\IT\python\pd\django_emr\venv\Lib\site-packages\django\db\models\query.py", line 1935, in _fetch_all
    self._result_cache = list(self._iterable_class(self))
                         ^^^^^^^^^^^^^^^^^^^^^^^^^^^^^^^^
  File "C:\Users\priya\OneDrive\Documents\IT\python\pd\django_emr\venv\Lib\site-packages\django\db\models\query.py", line 91, in __iter__
    results = compiler.execute_sql(
              ^^^^^^^^^^^^^^^^^^^^^
  File "C:\Users\priya\OneDrive\Documents\IT\python\pd\django_emr\venv\Lib\site-packages\django\db\models\sql\compiler.py", line 1622, in execute_sql
    cursor.execute(sql, params)
  File "C:\Users\priya\OneDrive\Documents\IT\python\pd\django_emr\venv\Lib\site-packages\django\db\backends\utils.py", line 122, in execute
    return super().execute(sql, params)
           ^^^^^^^^^^^^^^^^^^^^^^^^^^^^
  File "C:\Users\priya\OneDrive\Documents\IT\python\pd\django_emr\venv\Lib\site-packages\django\db\backends\utils.py", line 79, in execute
    return self._execute_with_wrappers(
           ^^^^^^^^^^^^^^^^^^^^^^^^^^^^
  File "C:\Users\priya\OneDrive\Documents\IT\python\pd\django_emr\venv\Lib\site-packages\django\db\backends\utils.py", line 92, in _execute_with_wrappers
    return executor(sql, params, many, context)
           ^^^^^^^^^^^^^^^^^^^^^^^^^^^^^^^^^^^^
  File "C:\Users\priya\OneDrive\Documents\IT\python\pd\django_emr\venv\Lib\site-packages\django\db\backends\utils.py", line 100, in _execute
    with self.db.wrap_database_errors:
         ^^^^^^^^^^^^^^^^^^^^^^^^^^^^
  File "C:\Users\priya\OneDrive\Documents\IT\python\pd\django_emr\venv\Lib\site-packages\django\db\utils.py", line 91, in __exit__
    raise dj_exc_value.with_traceback(traceback) from exc_value
  File "C:\Users\priya\OneDrive\Documents\IT\python\pd\django_emr\venv\Lib\site-packages\django\db\backends\utils.py", line 105, in _execute
    return self.cursor.execute(sql, params)
           ^^^^^^^^^^^^^^^^^^^^^^^^^^^^^^^^
  File "C:\Users\priya\OneDrive\Documents\IT\python\pd\django_emr\venv\Lib\site-packages\django\db\backends\mysql\base.py", line 76, in execute
    return self.cursor.execute(query, args)
           ^^^^^^^^^^^^^^^^^^^^^^^^^^^^^^^^
  File "C:\Users\priya\OneDrive\Documents\IT\python\pd\django_emr\venv\Lib\site-packages\MySQLdb\cursors.py", line 179, in execute
    res = self._query(mogrified_query)
          ^^^^^^^^^^^^^^^^^^^^^^^^^^^^
  File "C:\Users\priya\OneDrive\Documents\IT\python\pd\django_emr\venv\Lib\site-packages\MySQLdb\cursors.py", line 330, in _query
    db.query(q)
  File "C:\Users\priya\OneDrive\Documents\IT\python\pd\django_emr\venv\Lib\site-packages\MySQLdb\connections.py", line 280, in query
    _mysql.connection.query(self, query)
django.db.utils.ProgrammingError: (1146, "Table 'emr_db.emr_app_doctor' doesn't exist")
ERROR 2025-08-04 11:11:23,321 basehttp 15348 19628 "GET / HTTP/1.1" 500 195388
ERROR 2025-08-04 11:11:25,548 log 15348 19628 Internal Server Error: /
Traceback (most recent call last):
  File "C:\Users\priya\OneDrive\Documents\IT\python\pd\django_emr\venv\Lib\site-packages\django\db\models\fields\related_descriptors.py", line 513, in __get__
    rel_obj = self.related.get_cached_value(instance)
              ^^^^^^^^^^^^^^^^^^^^^^^^^^^^^^^^^^^^^^^
  File "C:\Users\priya\OneDrive\Documents\IT\python\pd\django_emr\venv\Lib\site-packages\django\db\models\fields\mixins.py", line 37, in get_cached_value
    return instance._state.fields_cache[self.cache_name]
           ~~~~~~~~~~~~~~~~~~~~~~~~~~~~^^^^^^^^^^^^^^^^^
KeyError: 'doctor_profile'

During handling of the above exception, another exception occurred:

Traceback (most recent call last):
  File "C:\Users\priya\OneDrive\Documents\IT\python\pd\django_emr\venv\Lib\site-packages\django\db\backends\utils.py", line 105, in _execute
    return self.cursor.execute(sql, params)
           ^^^^^^^^^^^^^^^^^^^^^^^^^^^^^^^^
  File "C:\Users\priya\OneDrive\Documents\IT\python\pd\django_emr\venv\Lib\site-packages\django\db\backends\mysql\base.py", line 76, in execute
    return self.cursor.execute(query, args)
           ^^^^^^^^^^^^^^^^^^^^^^^^^^^^^^^^
  File "C:\Users\priya\OneDrive\Documents\IT\python\pd\django_emr\venv\Lib\site-packages\MySQLdb\cursors.py", line 179, in execute
    res = self._query(mogrified_query)
          ^^^^^^^^^^^^^^^^^^^^^^^^^^^^
  File "C:\Users\priya\OneDrive\Documents\IT\python\pd\django_emr\venv\Lib\site-packages\MySQLdb\cursors.py", line 330, in _query
    db.query(q)
  File "C:\Users\priya\OneDrive\Documents\IT\python\pd\django_emr\venv\Lib\site-packages\MySQLdb\connections.py", line 280, in query
    _mysql.connection.query(self, query)
MySQLdb.ProgrammingError: (1146, "Table 'emr_db.emr_app_doctor' doesn't exist")

The above exception was the direct cause of the following exception:

Traceback (most recent call last):
  File "C:\Users\priya\OneDrive\Documents\IT\python\pd\django_emr\venv\Lib\site-packages\django\core\handlers\exception.py", line 55, in inner
    response = get_response(request)
               ^^^^^^^^^^^^^^^^^^^^^
  File "C:\Users\priya\OneDrive\Documents\IT\python\pd\django_emr\venv\Lib\site-packages\django\core\handlers\base.py", line 197, in _get_response
    response = wrapped_callback(request, *callback_args, **callback_kwargs)
               ^^^^^^^^^^^^^^^^^^^^^^^^^^^^^^^^^^^^^^^^^^^^^^^^^^^^^^^^^^^^
  File "C:\Users\priya\OneDrive\Documents\IT\python\pd\django_emr\venv\Lib\site-packages\django\contrib\auth\decorators.py", line 59, in _view_wrapper
    return view_func(request, *args, **kwargs)
           ^^^^^^^^^^^^^^^^^^^^^^^^^^^^^^^^^^^
  File "C:\Users\priya\OneDrive\Documents\IT\python\pd\django_emr\emr_project\emr_app\views.py", line 95, in home
    if request.user.is_staff or is_doctor(request.user):
                                ^^^^^^^^^^^^^^^^^^^^^^^
  File "C:\Users\priya\OneDrive\Documents\IT\python\pd\django_emr\emr_project\emr_app\views.py", line 27, in is_doctor
    return hasattr(user, 'doctor_profile') and user.doctor_profile.is_active
           ^^^^^^^^^^^^^^^^^^^^^^^^^^^^^^^
  File "C:\Users\priya\OneDrive\Documents\IT\python\pd\django_emr\venv\Lib\site-packages\django\utils\functional.py", line 253, in inner
    return func(_wrapped, *args)
           ^^^^^^^^^^^^^^^^^^^^^
  File "C:\Users\priya\OneDrive\Documents\IT\python\pd\django_emr\venv\Lib\site-packages\django\db\models\fields\related_descriptors.py", line 520, in __get__
    rel_obj = self.get_queryset(instance=instance).get(**filter_args)
              ^^^^^^^^^^^^^^^^^^^^^^^^^^^^^^^^^^^^^^^^^^^^^^^^^^^^^^^
  File "C:\Users\priya\OneDrive\Documents\IT\python\pd\django_emr\venv\Lib\site-packages\django\db\models\query.py", line 629, in get
    num = len(clone)
          ^^^^^^^^^^
  File "C:\Users\priya\OneDrive\Documents\IT\python\pd\django_emr\venv\Lib\site-packages\django\db\models\query.py", line 366, in __len__
    self._fetch_all()
  File "C:\Users\priya\OneDrive\Documents\IT\python\pd\django_emr\venv\Lib\site-packages\django\db\models\query.py", line 1935, in _fetch_all
    self._result_cache = list(self._iterable_class(self))
                         ^^^^^^^^^^^^^^^^^^^^^^^^^^^^^^^^
  File "C:\Users\priya\OneDrive\Documents\IT\python\pd\django_emr\venv\Lib\site-packages\django\db\models\query.py", line 91, in __iter__
    results = compiler.execute_sql(
              ^^^^^^^^^^^^^^^^^^^^^
  File "C:\Users\priya\OneDrive\Documents\IT\python\pd\django_emr\venv\Lib\site-packages\django\db\models\sql\compiler.py", line 1622, in execute_sql
    cursor.execute(sql, params)
  File "C:\Users\priya\OneDrive\Documents\IT\python\pd\django_emr\venv\Lib\site-packages\django\db\backends\utils.py", line 122, in execute
    return super().execute(sql, params)
           ^^^^^^^^^^^^^^^^^^^^^^^^^^^^
  File "C:\Users\priya\OneDrive\Documents\IT\python\pd\django_emr\venv\Lib\site-packages\django\db\backends\utils.py", line 79, in execute
    return self._execute_with_wrappers(
           ^^^^^^^^^^^^^^^^^^^^^^^^^^^^
  File "C:\Users\priya\OneDrive\Documents\IT\python\pd\django_emr\venv\Lib\site-packages\django\db\backends\utils.py", line 92, in _execute_with_wrappers
    return executor(sql, params, many, context)
           ^^^^^^^^^^^^^^^^^^^^^^^^^^^^^^^^^^^^
  File "C:\Users\priya\OneDrive\Documents\IT\python\pd\django_emr\venv\Lib\site-packages\django\db\backends\utils.py", line 100, in _execute
    with self.db.wrap_database_errors:
         ^^^^^^^^^^^^^^^^^^^^^^^^^^^^
  File "C:\Users\priya\OneDrive\Documents\IT\python\pd\django_emr\venv\Lib\site-packages\django\db\utils.py", line 91, in __exit__
    raise dj_exc_value.with_traceback(traceback) from exc_value
  File "C:\Users\priya\OneDrive\Documents\IT\python\pd\django_emr\venv\Lib\site-packages\django\db\backends\utils.py", line 105, in _execute
    return self.cursor.execute(sql, params)
           ^^^^^^^^^^^^^^^^^^^^^^^^^^^^^^^^
  File "C:\Users\priya\OneDrive\Documents\IT\python\pd\django_emr\venv\Lib\site-packages\django\db\backends\mysql\base.py", line 76, in execute
    return self.cursor.execute(query, args)
           ^^^^^^^^^^^^^^^^^^^^^^^^^^^^^^^^
  File "C:\Users\priya\OneDrive\Documents\IT\python\pd\django_emr\venv\Lib\site-packages\MySQLdb\cursors.py", line 179, in execute
    res = self._query(mogrified_query)
          ^^^^^^^^^^^^^^^^^^^^^^^^^^^^
  File "C:\Users\priya\OneDrive\Documents\IT\python\pd\django_emr\venv\Lib\site-packages\MySQLdb\cursors.py", line 330, in _query
    db.query(q)
  File "C:\Users\priya\OneDrive\Documents\IT\python\pd\django_emr\venv\Lib\site-packages\MySQLdb\connections.py", line 280, in query
    _mysql.connection.query(self, query)
django.db.utils.ProgrammingError: (1146, "Table 'emr_db.emr_app_doctor' doesn't exist")
ERROR 2025-08-04 11:11:25,557 basehttp 15348 19628 "GET / HTTP/1.1" 500 195388
INFO 2025-08-04 11:28:56,255 autoreload 15348 21356 C:\Users\priya\OneDrive\Documents\IT\python\pd\django_emr\emr_project\emr_project\settings.py changed, reloading.
INFO 2025-08-04 11:28:57,386 autoreload 17700 22628 Watching for file changes with StatReloader
INFO 2025-08-04 11:29:06,268 autoreload 17700 22628 C:\Users\priya\OneDrive\Documents\IT\python\pd\django_emr\emr_project\emr_project\settings.py changed, reloading.
INFO 2025-08-04 11:29:07,148 autoreload 19344 19332 Watching for file changes with StatReloader
INFO 2025-08-04 11:29:15,889 autoreload 19344 19332 C:\Users\priya\OneDrive\Documents\IT\python\pd\django_emr\emr_project\emr_project\settings.py changed, reloading.
INFO 2025-08-04 11:29:16,788 autoreload 12308 6480 Watching for file changes with StatReloader
INFO 2025-08-04 11:29:44,476 autoreload 12308 6480 C:\Users\priya\OneDrive\Documents\IT\python\pd\django_emr\emr_project\emr_project\settings.py changed, reloading.
INFO 2025-08-04 11:29:45,253 autoreload 22636 5472 Watching for file changes with StatReloader
INFO 2025-08-04 11:32:03,247 autoreload 22636 5472 C:\Users\priya\OneDrive\Documents\IT\python\pd\django_emr\emr_project\emr_project\settings.py changed, reloading.
INFO 2025-08-04 11:32:04,678 autoreload 25216 17836 Watching for file changes with StatReloader
INFO 2025-08-04 11:40:04,169 autoreload 25216 17836 C:\Users\priya\OneDrive\Documents\IT\python\pd\django_emr\emr_project\emr_project\settings.py changed, reloading.
INFO 2025-08-04 11:40:05,192 autoreload 3476 19432 Watching for file changes with StatReloader
INFO 2025-08-04 11:44:35,906 autoreload 3476 19432 C:\Users\priya\OneDrive\Documents\IT\python\pd\django_emr\emr_project\emr_project\settings.py changed, reloading.
INFO 2025-08-04 11:44:37,066 autoreload 22080 9580 Watching for file changes with StatReloader
INFO 2025-08-04 11:44:45,898 autoreload 21356 22512 Watching for file changes with StatReloader
INFO 2025-08-04 14:04:26,227 autoreload 6504 5160 Watching for file changes with StatReloader
INFO 2025-08-04 14:05:15,131 basehttp 6504 10600 "GET / HTTP/1.1" 302 0
INFO 2025-08-04 14:05:15,275 basehttp 6504 10600 "GET /login/?next=/ HTTP/1.1" 200 13693
WARNING 2025-08-04 14:05:15,609 log 6504 10600 Not Found: /favicon.ico
WARNING 2025-08-04 14:05:15,609 basehttp 6504 10600 "GET /favicon.ico HTTP/1.1" 404 7036
ERROR 2025-08-04 14:05:18,086 log 6504 10600 Internal Server Error: /login/
Traceback (most recent call last):
  File "C:\Users\priya\AppData\Local\Packages\PythonSoftwareFoundation.Python.3.12_qbz5n2kfra8p0\LocalCache\local-packages\Python312\site-packages\django\db\backends\utils.py", line 105, in _execute
    return self.cursor.execute(sql, params)
           ^^^^^^^^^^^^^^^^^^^^^^^^^^^^^^^^
  File "C:\Users\priya\AppData\Local\Packages\PythonSoftwareFoundation.Python.3.12_qbz5n2kfra8p0\LocalCache\local-packages\Python312\site-packages\django\db\backends\mysql\base.py", line 76, in execute
    return self.cursor.execute(query, args)
           ^^^^^^^^^^^^^^^^^^^^^^^^^^^^^^^^
  File "C:\Users\priya\AppData\Local\Packages\PythonSoftwareFoundation.Python.3.12_qbz5n2kfra8p0\LocalCache\local-packages\Python312\site-packages\MySQLdb\cursors.py", line 179, in execute
    res = self._query(mogrified_query)
          ^^^^^^^^^^^^^^^^^^^^^^^^^^^^
  File "C:\Users\priya\AppData\Local\Packages\PythonSoftwareFoundation.Python.3.12_qbz5n2kfra8p0\LocalCache\local-packages\Python312\site-packages\MySQLdb\cursors.py", line 330, in _query
    db.query(q)
  File "C:\Users\priya\AppData\Local\Packages\PythonSoftwareFoundation.Python.3.12_qbz5n2kfra8p0\LocalCache\local-packages\Python312\site-packages\MySQLdb\connections.py", line 257, in query
    _mysql.connection.query(self, query)
MySQLdb.ProgrammingError: (1146, "Table 'emr_db.axes_accessattempt' doesn't exist")

The above exception was the direct cause of the following exception:

Traceback (most recent call last):
  File "C:\Users\priya\AppData\Local\Packages\PythonSoftwareFoundation.Python.3.12_qbz5n2kfra8p0\LocalCache\local-packages\Python312\site-packages\django\core\handlers\exception.py", line 55, in inner
    response = get_response(request)
               ^^^^^^^^^^^^^^^^^^^^^
  File "C:\Users\priya\AppData\Local\Packages\PythonSoftwareFoundation.Python.3.12_qbz5n2kfra8p0\LocalCache\local-packages\Python312\site-packages\django\core\handlers\base.py", line 197, in _get_response
    response = wrapped_callback(request, *callback_args, **callback_kwargs)
               ^^^^^^^^^^^^^^^^^^^^^^^^^^^^^^^^^^^^^^^^^^^^^^^^^^^^^^^^^^^^
  File "C:\Users\priya\AppData\Local\Packages\PythonSoftwareFoundation.Python.3.12_qbz5n2kfra8p0\LocalCache\local-packages\Python312\site-packages\django\views\generic\base.py", line 104, in view
    return self.dispatch(request, *args, **kwargs)
           ^^^^^^^^^^^^^^^^^^^^^^^^^^^^^^^^^^^^^^^
  File "C:\Users\priya\AppData\Local\Packages\PythonSoftwareFoundation.Python.3.12_qbz5n2kfra8p0\LocalCache\local-packages\Python312\site-packages\django\utils\decorators.py", line 48, in _wrapper
    return bound_method(*args, **kwargs)
           ^^^^^^^^^^^^^^^^^^^^^^^^^^^^^
  File "C:\Users\priya\AppData\Local\Packages\PythonSoftwareFoundation.Python.3.12_qbz5n2kfra8p0\LocalCache\local-packages\Python312\site-packages\django\views\decorators\debug.py", line 143, in sensitive_post_parameters_wrapper
    return view(request, *args, **kwargs)
           ^^^^^^^^^^^^^^^^^^^^^^^^^^^^^^
  File "C:\Users\priya\AppData\Local\Packages\PythonSoftwareFoundation.Python.3.12_qbz5n2kfra8p0\LocalCache\local-packages\Python312\site-packages\django\utils\decorators.py", line 48, in _wrapper
    return bound_method(*args, **kwargs)
           ^^^^^^^^^^^^^^^^^^^^^^^^^^^^^
  File "C:\Users\priya\AppData\Local\Packages\PythonSoftwareFoundation.Python.3.12_qbz5n2kfra8p0\LocalCache\local-packages\Python312\site-packages\django\utils\decorators.py", line 188, in _view_wrapper
    result = _process_exception(request, e)
             ^^^^^^^^^^^^^^^^^^^^^^^^^^^^^^
  File "C:\Users\priya\AppData\Local\Packages\PythonSoftwareFoundation.Python.3.12_qbz5n2kfra8p0\LocalCache\local-packages\Python312\site-packages\django\utils\decorators.py", line 186, in _view_wrapper
    response = view_func(request, *args, **kwargs)
               ^^^^^^^^^^^^^^^^^^^^^^^^^^^^^^^^^^^
  File "C:\Users\priya\AppData\Local\Packages\PythonSoftwareFoundation.Python.3.12_qbz5n2kfra8p0\LocalCache\local-packages\Python312\site-packages\django\utils\decorators.py", line 48, in _wrapper
    return bound_method(*args, **kwargs)
           ^^^^^^^^^^^^^^^^^^^^^^^^^^^^^
  File "C:\Users\priya\AppData\Local\Packages\PythonSoftwareFoundation.Python.3.12_qbz5n2kfra8p0\LocalCache\local-packages\Python312\site-packages\django\views\decorators\cache.py", line 80, in _view_wrapper
    response = view_func(request, *args, **kwargs)
               ^^^^^^^^^^^^^^^^^^^^^^^^^^^^^^^^^^^
  File "C:\Users\priya\AppData\Local\Packages\PythonSoftwareFoundation.Python.3.12_qbz5n2kfra8p0\LocalCache\local-packages\Python312\site-packages\django\contrib\auth\views.py", line 88, in dispatch
    return super().dispatch(request, *args, **kwargs)
           ^^^^^^^^^^^^^^^^^^^^^^^^^^^^^^^^^^^^^^^^^^
  File "C:\Users\priya\AppData\Local\Packages\PythonSoftwareFoundation.Python.3.12_qbz5n2kfra8p0\LocalCache\local-packages\Python312\site-packages\django\views\generic\base.py", line 143, in dispatch
    return handler(request, *args, **kwargs)
           ^^^^^^^^^^^^^^^^^^^^^^^^^^^^^^^^^
  File "C:\Users\priya\AppData\Local\Packages\PythonSoftwareFoundation.Python.3.12_qbz5n2kfra8p0\LocalCache\local-packages\Python312\site-packages\django\views\generic\edit.py", line 150, in post
    if form.is_valid():
       ^^^^^^^^^^^^^^^
  File "C:\Users\priya\AppData\Local\Packages\PythonSoftwareFoundation.Python.3.12_qbz5n2kfra8p0\LocalCache\local-packages\Python312\site-packages\django\forms\forms.py", line 197, in is_valid
    return self.is_bound and not self.errors
                                 ^^^^^^^^^^^
  File "C:\Users\priya\AppData\Local\Packages\PythonSoftwareFoundation.Python.3.12_qbz5n2kfra8p0\LocalCache\local-packages\Python312\site-packages\django\forms\forms.py", line 192, in errors
    self.full_clean()
  File "C:\Users\priya\AppData\Local\Packages\PythonSoftwareFoundation.Python.3.12_qbz5n2kfra8p0\LocalCache\local-packages\Python312\site-packages\django\forms\forms.py", line 328, in full_clean
    self._clean_form()
  File "C:\Users\priya\AppData\Local\Packages\PythonSoftwareFoundation.Python.3.12_qbz5n2kfra8p0\LocalCache\local-packages\Python312\site-packages\django\forms\forms.py", line 349, in _clean_form
    cleaned_data = self.clean()
                   ^^^^^^^^^^^^
  File "C:\Users\priya\AppData\Local\Packages\PythonSoftwareFoundation.Python.3.12_qbz5n2kfra8p0\LocalCache\local-packages\Python312\site-packages\django\contrib\auth\forms.py", line 252, in clean
    self.user_cache = authenticate(
                      ^^^^^^^^^^^^^
  File "C:\Users\priya\AppData\Local\Packages\PythonSoftwareFoundation.Python.3.12_qbz5n2kfra8p0\LocalCache\local-packages\Python312\site-packages\django\views\decorators\debug.py", line 75, in sensitive_variables_wrapper
    return func(*func_args, **func_kwargs)
           ^^^^^^^^^^^^^^^^^^^^^^^^^^^^^^^
  File "C:\Users\priya\AppData\Local\Packages\PythonSoftwareFoundation.Python.3.12_qbz5n2kfra8p0\LocalCache\local-packages\Python312\site-packages\django\contrib\auth\__init__.py", line 79, in authenticate
    user = backend.authenticate(request, **credentials)
           ^^^^^^^^^^^^^^^^^^^^^^^^^^^^^^^^^^^^^^^^^^^^
  File "C:\Users\priya\AppData\Local\Packages\PythonSoftwareFoundation.Python.3.12_qbz5n2kfra8p0\LocalCache\local-packages\Python312\site-packages\axes\helpers.py", line 614, in inner
    return func(*args, **kwargs)
           ^^^^^^^^^^^^^^^^^^^^^
  File "C:\Users\priya\AppData\Local\Packages\PythonSoftwareFoundation.Python.3.12_qbz5n2kfra8p0\LocalCache\local-packages\Python312\site-packages\axes\backends.py", line 52, in authenticate
    if AxesProxyHandler.is_allowed(request, credentials):
       ^^^^^^^^^^^^^^^^^^^^^^^^^^^^^^^^^^^^^^^^^^^^^^^^^
  File "C:\Users\priya\AppData\Local\Packages\PythonSoftwareFoundation.Python.3.12_qbz5n2kfra8p0\LocalCache\local-packages\Python312\site-packages\axes\handlers\proxy.py", line 108, in is_allowed
    return cls.get_implementation().is_allowed(request, credentials)
           ^^^^^^^^^^^^^^^^^^^^^^^^^^^^^^^^^^^^^^^^^^^^^^^^^^^^^^^^^
  File "C:\Users\priya\AppData\Local\Packages\PythonSoftwareFoundation.Python.3.12_qbz5n2kfra8p0\LocalCache\local-packages\Python312\site-packages\axes\handlers\base.py", line 94, in is_allowed
    if self.is_locked(request, credentials):
       ^^^^^^^^^^^^^^^^^^^^^^^^^^^^^^^^^^^^
  File "C:\Users\priya\AppData\Local\Packages\PythonSoftwareFoundation.Python.3.12_qbz5n2kfra8p0\LocalCache\local-packages\Python312\site-packages\axes\handlers\base.py", line 132, in is_locked
    return self.get_failures(  # type: ignore
           ^^^^^^^^^^^^^^^^^^^^^^^^^^^^^^^^^^
  File "C:\Users\priya\AppData\Local\Packages\PythonSoftwareFoundation.Python.3.12_qbz5n2kfra8p0\LocalCache\local-packages\Python312\site-packages\axes\handlers\database.py", line 107, in get_failures
    attempt_count = max(
                    ^^^^
  File "C:\Users\priya\AppData\Local\Packages\PythonSoftwareFoundation.Python.3.12_qbz5n2kfra8p0\LocalCache\local-packages\Python312\site-packages\axes\handlers\database.py", line 109, in <genexpr>
    attempts.aggregate(Sum("failures_since_start"))[
    ^^^^^^^^^^^^^^^^^^^^^^^^^^^^^^^^^^^^^^^^^^^^^^^
  File "C:\Users\priya\AppData\Local\Packages\PythonSoftwareFoundation.Python.3.12_qbz5n2kfra8p0\LocalCache\local-packages\Python312\site-packages\django\db\models\query.py", line 604, in aggregate
    return self.query.chain().get_aggregation(self.db, kwargs)
           ^^^^^^^^^^^^^^^^^^^^^^^^^^^^^^^^^^^^^^^^^^^^^^^^^^^
  File "C:\Users\priya\AppData\Local\Packages\PythonSoftwareFoundation.Python.3.12_qbz5n2kfra8p0\LocalCache\local-packages\Python312\site-packages\django\db\models\sql\query.py", line 615, in get_aggregation
    result = compiler.execute_sql(SINGLE)
             ^^^^^^^^^^^^^^^^^^^^^^^^^^^^
  File "C:\Users\priya\AppData\Local\Packages\PythonSoftwareFoundation.Python.3.12_qbz5n2kfra8p0\LocalCache\local-packages\Python312\site-packages\django\db\models\sql\compiler.py", line 1562, in execute_sql
    cursor.execute(sql, params)
  File "C:\Users\priya\AppData\Local\Packages\PythonSoftwareFoundation.Python.3.12_qbz5n2kfra8p0\LocalCache\local-packages\Python312\site-packages\django\db\backends\utils.py", line 122, in execute
    return super().execute(sql, params)
           ^^^^^^^^^^^^^^^^^^^^^^^^^^^^
  File "C:\Users\priya\AppData\Local\Packages\PythonSoftwareFoundation.Python.3.12_qbz5n2kfra8p0\LocalCache\local-packages\Python312\site-packages\django\db\backends\utils.py", line 79, in execute
    return self._execute_with_wrappers(
           ^^^^^^^^^^^^^^^^^^^^^^^^^^^^
  File "C:\Users\priya\AppData\Local\Packages\PythonSoftwareFoundation.Python.3.12_qbz5n2kfra8p0\LocalCache\local-packages\Python312\site-packages\django\db\backends\utils.py", line 92, in _execute_with_wrappers
    return executor(sql, params, many, context)
           ^^^^^^^^^^^^^^^^^^^^^^^^^^^^^^^^^^^^
  File "C:\Users\priya\AppData\Local\Packages\PythonSoftwareFoundation.Python.3.12_qbz5n2kfra8p0\LocalCache\local-packages\Python312\site-packages\django\db\backends\utils.py", line 100, in _execute
    with self.db.wrap_database_errors:
         ^^^^^^^^^^^^^^^^^^^^^^^^^^^^
  File "C:\Users\priya\AppData\Local\Packages\PythonSoftwareFoundation.Python.3.12_qbz5n2kfra8p0\LocalCache\local-packages\Python312\site-packages\django\db\utils.py", line 91, in __exit__
    raise dj_exc_value.with_traceback(traceback) from exc_value
  File "C:\Users\priya\AppData\Local\Packages\PythonSoftwareFoundation.Python.3.12_qbz5n2kfra8p0\LocalCache\local-packages\Python312\site-packages\django\db\backends\utils.py", line 105, in _execute
    return self.cursor.execute(sql, params)
           ^^^^^^^^^^^^^^^^^^^^^^^^^^^^^^^^
  File "C:\Users\priya\AppData\Local\Packages\PythonSoftwareFoundation.Python.3.12_qbz5n2kfra8p0\LocalCache\local-packages\Python312\site-packages\django\db\backends\mysql\base.py", line 76, in execute
    return self.cursor.execute(query, args)
           ^^^^^^^^^^^^^^^^^^^^^^^^^^^^^^^^
  File "C:\Users\priya\AppData\Local\Packages\PythonSoftwareFoundation.Python.3.12_qbz5n2kfra8p0\LocalCache\local-packages\Python312\site-packages\MySQLdb\cursors.py", line 179, in execute
    res = self._query(mogrified_query)
          ^^^^^^^^^^^^^^^^^^^^^^^^^^^^
  File "C:\Users\priya\AppData\Local\Packages\PythonSoftwareFoundation.Python.3.12_qbz5n2kfra8p0\LocalCache\local-packages\Python312\site-packages\MySQLdb\cursors.py", line 330, in _query
    db.query(q)
  File "C:\Users\priya\AppData\Local\Packages\PythonSoftwareFoundation.Python.3.12_qbz5n2kfra8p0\LocalCache\local-packages\Python312\site-packages\MySQLdb\connections.py", line 257, in query
    _mysql.connection.query(self, query)
django.db.utils.ProgrammingError: (1146, "Table 'emr_db.axes_accessattempt' doesn't exist")
ERROR 2025-08-04 14:05:18,106 basehttp 6504 10600 "POST /login/?next=/ HTTP/1.1" 500 286405
INFO 2025-08-04 14:05:20,222 basehttp 6504 10600 "GET /login/?next=/ HTTP/1.1" 200 13693
INFO 2025-08-04 14:05:22,212 basehttp 6504 10600 "GET /login/ HTTP/1.1" 200 13693
INFO 2025-08-04 14:05:26,260 basehttp 6504 10600 "GET /signup/ HTTP/1.1" 200 15363
INFO 2025-08-04 14:05:29,473 basehttp 6504 10600 "GET /login/ HTTP/1.1" 200 13693
INFO 2025-08-04 14:05:30,698 basehttp 6504 10600 "GET / HTTP/1.1" 302 0
INFO 2025-08-04 14:05:30,708 basehttp 6504 10600 "GET /login/?next=/ HTTP/1.1" 200 13693
ERROR 2025-08-04 14:05:32,593 log 6504 10600 Internal Server Error: /login/
Traceback (most recent call last):
  File "C:\Users\priya\AppData\Local\Packages\PythonSoftwareFoundation.Python.3.12_qbz5n2kfra8p0\LocalCache\local-packages\Python312\site-packages\django\db\backends\utils.py", line 105, in _execute
    return self.cursor.execute(sql, params)
           ^^^^^^^^^^^^^^^^^^^^^^^^^^^^^^^^
  File "C:\Users\priya\AppData\Local\Packages\PythonSoftwareFoundation.Python.3.12_qbz5n2kfra8p0\LocalCache\local-packages\Python312\site-packages\django\db\backends\mysql\base.py", line 76, in execute
    return self.cursor.execute(query, args)
           ^^^^^^^^^^^^^^^^^^^^^^^^^^^^^^^^
  File "C:\Users\priya\AppData\Local\Packages\PythonSoftwareFoundation.Python.3.12_qbz5n2kfra8p0\LocalCache\local-packages\Python312\site-packages\MySQLdb\cursors.py", line 179, in execute
    res = self._query(mogrified_query)
          ^^^^^^^^^^^^^^^^^^^^^^^^^^^^
  File "C:\Users\priya\AppData\Local\Packages\PythonSoftwareFoundation.Python.3.12_qbz5n2kfra8p0\LocalCache\local-packages\Python312\site-packages\MySQLdb\cursors.py", line 330, in _query
    db.query(q)
  File "C:\Users\priya\AppData\Local\Packages\PythonSoftwareFoundation.Python.3.12_qbz5n2kfra8p0\LocalCache\local-packages\Python312\site-packages\MySQLdb\connections.py", line 257, in query
    _mysql.connection.query(self, query)
MySQLdb.ProgrammingError: (1146, "Table 'emr_db.axes_accessattempt' doesn't exist")

The above exception was the direct cause of the following exception:

Traceback (most recent call last):
  File "C:\Users\priya\AppData\Local\Packages\PythonSoftwareFoundation.Python.3.12_qbz5n2kfra8p0\LocalCache\local-packages\Python312\site-packages\django\core\handlers\exception.py", line 55, in inner
    response = get_response(request)
               ^^^^^^^^^^^^^^^^^^^^^
  File "C:\Users\priya\AppData\Local\Packages\PythonSoftwareFoundation.Python.3.12_qbz5n2kfra8p0\LocalCache\local-packages\Python312\site-packages\django\core\handlers\base.py", line 197, in _get_response
    response = wrapped_callback(request, *callback_args, **callback_kwargs)
               ^^^^^^^^^^^^^^^^^^^^^^^^^^^^^^^^^^^^^^^^^^^^^^^^^^^^^^^^^^^^
  File "C:\Users\priya\AppData\Local\Packages\PythonSoftwareFoundation.Python.3.12_qbz5n2kfra8p0\LocalCache\local-packages\Python312\site-packages\django\views\generic\base.py", line 104, in view
    return self.dispatch(request, *args, **kwargs)
           ^^^^^^^^^^^^^^^^^^^^^^^^^^^^^^^^^^^^^^^
  File "C:\Users\priya\AppData\Local\Packages\PythonSoftwareFoundation.Python.3.12_qbz5n2kfra8p0\LocalCache\local-packages\Python312\site-packages\django\utils\decorators.py", line 48, in _wrapper
    return bound_method(*args, **kwargs)
           ^^^^^^^^^^^^^^^^^^^^^^^^^^^^^
  File "C:\Users\priya\AppData\Local\Packages\PythonSoftwareFoundation.Python.3.12_qbz5n2kfra8p0\LocalCache\local-packages\Python312\site-packages\django\views\decorators\debug.py", line 143, in sensitive_post_parameters_wrapper
    return view(request, *args, **kwargs)
           ^^^^^^^^^^^^^^^^^^^^^^^^^^^^^^
  File "C:\Users\priya\AppData\Local\Packages\PythonSoftwareFoundation.Python.3.12_qbz5n2kfra8p0\LocalCache\local-packages\Python312\site-packages\django\utils\decorators.py", line 48, in _wrapper
    return bound_method(*args, **kwargs)
           ^^^^^^^^^^^^^^^^^^^^^^^^^^^^^
  File "C:\Users\priya\AppData\Local\Packages\PythonSoftwareFoundation.Python.3.12_qbz5n2kfra8p0\LocalCache\local-packages\Python312\site-packages\django\utils\decorators.py", line 188, in _view_wrapper
    result = _process_exception(request, e)
             ^^^^^^^^^^^^^^^^^^^^^^^^^^^^^^
  File "C:\Users\priya\AppData\Local\Packages\PythonSoftwareFoundation.Python.3.12_qbz5n2kfra8p0\LocalCache\local-packages\Python312\site-packages\django\utils\decorators.py", line 186, in _view_wrapper
    response = view_func(request, *args, **kwargs)
               ^^^^^^^^^^^^^^^^^^^^^^^^^^^^^^^^^^^
  File "C:\Users\priya\AppData\Local\Packages\PythonSoftwareFoundation.Python.3.12_qbz5n2kfra8p0\LocalCache\local-packages\Python312\site-packages\django\utils\decorators.py", line 48, in _wrapper
    return bound_method(*args, **kwargs)
           ^^^^^^^^^^^^^^^^^^^^^^^^^^^^^
  File "C:\Users\priya\AppData\Local\Packages\PythonSoftwareFoundation.Python.3.12_qbz5n2kfra8p0\LocalCache\local-packages\Python312\site-packages\django\views\decorators\cache.py", line 80, in _view_wrapper
    response = view_func(request, *args, **kwargs)
               ^^^^^^^^^^^^^^^^^^^^^^^^^^^^^^^^^^^
  File "C:\Users\priya\AppData\Local\Packages\PythonSoftwareFoundation.Python.3.12_qbz5n2kfra8p0\LocalCache\local-packages\Python312\site-packages\django\contrib\auth\views.py", line 88, in dispatch
    return super().dispatch(request, *args, **kwargs)
           ^^^^^^^^^^^^^^^^^^^^^^^^^^^^^^^^^^^^^^^^^^
  File "C:\Users\priya\AppData\Local\Packages\PythonSoftwareFoundation.Python.3.12_qbz5n2kfra8p0\LocalCache\local-packages\Python312\site-packages\django\views\generic\base.py", line 143, in dispatch
    return handler(request, *args, **kwargs)
           ^^^^^^^^^^^^^^^^^^^^^^^^^^^^^^^^^
  File "C:\Users\priya\AppData\Local\Packages\PythonSoftwareFoundation.Python.3.12_qbz5n2kfra8p0\LocalCache\local-packages\Python312\site-packages\django\views\generic\edit.py", line 150, in post
    if form.is_valid():
       ^^^^^^^^^^^^^^^
  File "C:\Users\priya\AppData\Local\Packages\PythonSoftwareFoundation.Python.3.12_qbz5n2kfra8p0\LocalCache\local-packages\Python312\site-packages\django\forms\forms.py", line 197, in is_valid
    return self.is_bound and not self.errors
                                 ^^^^^^^^^^^
  File "C:\Users\priya\AppData\Local\Packages\PythonSoftwareFoundation.Python.3.12_qbz5n2kfra8p0\LocalCache\local-packages\Python312\site-packages\django\forms\forms.py", line 192, in errors
    self.full_clean()
  File "C:\Users\priya\AppData\Local\Packages\PythonSoftwareFoundation.Python.3.12_qbz5n2kfra8p0\LocalCache\local-packages\Python312\site-packages\django\forms\forms.py", line 328, in full_clean
    self._clean_form()
  File "C:\Users\priya\AppData\Local\Packages\PythonSoftwareFoundation.Python.3.12_qbz5n2kfra8p0\LocalCache\local-packages\Python312\site-packages\django\forms\forms.py", line 349, in _clean_form
    cleaned_data = self.clean()
                   ^^^^^^^^^^^^
  File "C:\Users\priya\AppData\Local\Packages\PythonSoftwareFoundation.Python.3.12_qbz5n2kfra8p0\LocalCache\local-packages\Python312\site-packages\django\contrib\auth\forms.py", line 252, in clean
    self.user_cache = authenticate(
                      ^^^^^^^^^^^^^
  File "C:\Users\priya\AppData\Local\Packages\PythonSoftwareFoundation.Python.3.12_qbz5n2kfra8p0\LocalCache\local-packages\Python312\site-packages\django\views\decorators\debug.py", line 75, in sensitive_variables_wrapper
    return func(*func_args, **func_kwargs)
           ^^^^^^^^^^^^^^^^^^^^^^^^^^^^^^^
  File "C:\Users\priya\AppData\Local\Packages\PythonSoftwareFoundation.Python.3.12_qbz5n2kfra8p0\LocalCache\local-packages\Python312\site-packages\django\contrib\auth\__init__.py", line 79, in authenticate
    user = backend.authenticate(request, **credentials)
           ^^^^^^^^^^^^^^^^^^^^^^^^^^^^^^^^^^^^^^^^^^^^
  File "C:\Users\priya\AppData\Local\Packages\PythonSoftwareFoundation.Python.3.12_qbz5n2kfra8p0\LocalCache\local-packages\Python312\site-packages\axes\helpers.py", line 614, in inner
    return func(*args, **kwargs)
           ^^^^^^^^^^^^^^^^^^^^^
  File "C:\Users\priya\AppData\Local\Packages\PythonSoftwareFoundation.Python.3.12_qbz5n2kfra8p0\LocalCache\local-packages\Python312\site-packages\axes\backends.py", line 52, in authenticate
    if AxesProxyHandler.is_allowed(request, credentials):
       ^^^^^^^^^^^^^^^^^^^^^^^^^^^^^^^^^^^^^^^^^^^^^^^^^
  File "C:\Users\priya\AppData\Local\Packages\PythonSoftwareFoundation.Python.3.12_qbz5n2kfra8p0\LocalCache\local-packages\Python312\site-packages\axes\handlers\proxy.py", line 108, in is_allowed
    return cls.get_implementation().is_allowed(request, credentials)
           ^^^^^^^^^^^^^^^^^^^^^^^^^^^^^^^^^^^^^^^^^^^^^^^^^^^^^^^^^
  File "C:\Users\priya\AppData\Local\Packages\PythonSoftwareFoundation.Python.3.12_qbz5n2kfra8p0\LocalCache\local-packages\Python312\site-packages\axes\handlers\base.py", line 94, in is_allowed
    if self.is_locked(request, credentials):
       ^^^^^^^^^^^^^^^^^^^^^^^^^^^^^^^^^^^^
  File "C:\Users\priya\AppData\Local\Packages\PythonSoftwareFoundation.Python.3.12_qbz5n2kfra8p0\LocalCache\local-packages\Python312\site-packages\axes\handlers\base.py", line 132, in is_locked
    return self.get_failures(  # type: ignore
           ^^^^^^^^^^^^^^^^^^^^^^^^^^^^^^^^^^
  File "C:\Users\priya\AppData\Local\Packages\PythonSoftwareFoundation.Python.3.12_qbz5n2kfra8p0\LocalCache\local-packages\Python312\site-packages\axes\handlers\database.py", line 107, in get_failures
    attempt_count = max(
                    ^^^^
  File "C:\Users\priya\AppData\Local\Packages\PythonSoftwareFoundation.Python.3.12_qbz5n2kfra8p0\LocalCache\local-packages\Python312\site-packages\axes\handlers\database.py", line 109, in <genexpr>
    attempts.aggregate(Sum("failures_since_start"))[
    ^^^^^^^^^^^^^^^^^^^^^^^^^^^^^^^^^^^^^^^^^^^^^^^
  File "C:\Users\priya\AppData\Local\Packages\PythonSoftwareFoundation.Python.3.12_qbz5n2kfra8p0\LocalCache\local-packages\Python312\site-packages\django\db\models\query.py", line 604, in aggregate
    return self.query.chain().get_aggregation(self.db, kwargs)
           ^^^^^^^^^^^^^^^^^^^^^^^^^^^^^^^^^^^^^^^^^^^^^^^^^^^
  File "C:\Users\priya\AppData\Local\Packages\PythonSoftwareFoundation.Python.3.12_qbz5n2kfra8p0\LocalCache\local-packages\Python312\site-packages\django\db\models\sql\query.py", line 615, in get_aggregation
    result = compiler.execute_sql(SINGLE)
             ^^^^^^^^^^^^^^^^^^^^^^^^^^^^
  File "C:\Users\priya\AppData\Local\Packages\PythonSoftwareFoundation.Python.3.12_qbz5n2kfra8p0\LocalCache\local-packages\Python312\site-packages\django\db\models\sql\compiler.py", line 1562, in execute_sql
    cursor.execute(sql, params)
  File "C:\Users\priya\AppData\Local\Packages\PythonSoftwareFoundation.Python.3.12_qbz5n2kfra8p0\LocalCache\local-packages\Python312\site-packages\django\db\backends\utils.py", line 122, in execute
    return super().execute(sql, params)
           ^^^^^^^^^^^^^^^^^^^^^^^^^^^^
  File "C:\Users\priya\AppData\Local\Packages\PythonSoftwareFoundation.Python.3.12_qbz5n2kfra8p0\LocalCache\local-packages\Python312\site-packages\django\db\backends\utils.py", line 79, in execute
    return self._execute_with_wrappers(
           ^^^^^^^^^^^^^^^^^^^^^^^^^^^^
  File "C:\Users\priya\AppData\Local\Packages\PythonSoftwareFoundation.Python.3.12_qbz5n2kfra8p0\LocalCache\local-packages\Python312\site-packages\django\db\backends\utils.py", line 92, in _execute_with_wrappers
    return executor(sql, params, many, context)
           ^^^^^^^^^^^^^^^^^^^^^^^^^^^^^^^^^^^^
  File "C:\Users\priya\AppData\Local\Packages\PythonSoftwareFoundation.Python.3.12_qbz5n2kfra8p0\LocalCache\local-packages\Python312\site-packages\django\db\backends\utils.py", line 100, in _execute
    with self.db.wrap_database_errors:
         ^^^^^^^^^^^^^^^^^^^^^^^^^^^^
  File "C:\Users\priya\AppData\Local\Packages\PythonSoftwareFoundation.Python.3.12_qbz5n2kfra8p0\LocalCache\local-packages\Python312\site-packages\django\db\utils.py", line 91, in __exit__
    raise dj_exc_value.with_traceback(traceback) from exc_value
  File "C:\Users\priya\AppData\Local\Packages\PythonSoftwareFoundation.Python.3.12_qbz5n2kfra8p0\LocalCache\local-packages\Python312\site-packages\django\db\backends\utils.py", line 105, in _execute
    return self.cursor.execute(sql, params)
           ^^^^^^^^^^^^^^^^^^^^^^^^^^^^^^^^
  File "C:\Users\priya\AppData\Local\Packages\PythonSoftwareFoundation.Python.3.12_qbz5n2kfra8p0\LocalCache\local-packages\Python312\site-packages\django\db\backends\mysql\base.py", line 76, in execute
    return self.cursor.execute(query, args)
           ^^^^^^^^^^^^^^^^^^^^^^^^^^^^^^^^
  File "C:\Users\priya\AppData\Local\Packages\PythonSoftwareFoundation.Python.3.12_qbz5n2kfra8p0\LocalCache\local-packages\Python312\site-packages\MySQLdb\cursors.py", line 179, in execute
    res = self._query(mogrified_query)
          ^^^^^^^^^^^^^^^^^^^^^^^^^^^^
  File "C:\Users\priya\AppData\Local\Packages\PythonSoftwareFoundation.Python.3.12_qbz5n2kfra8p0\LocalCache\local-packages\Python312\site-packages\MySQLdb\cursors.py", line 330, in _query
    db.query(q)
  File "C:\Users\priya\AppData\Local\Packages\PythonSoftwareFoundation.Python.3.12_qbz5n2kfra8p0\LocalCache\local-packages\Python312\site-packages\MySQLdb\connections.py", line 257, in query
    _mysql.connection.query(self, query)
django.db.utils.ProgrammingError: (1146, "Table 'emr_db.axes_accessattempt' doesn't exist")
ERROR 2025-08-04 14:05:32,601 basehttp 6504 10600 "POST /login/?next=/ HTTP/1.1" 500 286405
INFO 2025-08-04 14:19:50,547 autoreload 6504 5160 C:\Users\priya\OneDrive\Documents\IT\python\pd\django_emr\emr_project\emr_project\settings.py changed, reloading.
INFO 2025-08-04 14:19:57,396 autoreload 18160 9632 Watching for file changes with StatReloader
INFO 2025-08-04 14:20:35,564 autoreload 18160 9632 C:\Users\priya\OneDrive\Documents\IT\python\pd\django_emr\emr_project\emr_project\settings.py changed, reloading.
INFO 2025-08-04 14:20:36,210 autoreload 14340 18292 Watching for file changes with StatReloader
INFO 2025-08-04 14:29:57,222 autoreload 19984 23132 Watching for file changes with StatReloader
INFO 2025-08-04 14:50:51,202 autoreload 19640 9104 Watching for file changes with StatReloader
INFO 2025-08-04 14:51:50,145 autoreload 18516 4488 Watching for file changes with StatReloader
INFO 2025-08-04 14:51:58,282 basehttp 18516 11580 "GET /login/?next=/ HTTP/1.1" 200 13693
INFO 2025-08-04 14:52:01,614 basehttp 18516 11580 "POST /login/?next=/ HTTP/1.1" 302 0
ERROR 2025-08-04 14:52:01,851 log 18516 11580 Internal Server Error: /
Traceback (most recent call last):
  File "C:\Users\priya\OneDrive\Documents\IT\python\pd\django_emr\venv\Lib\site-packages\django\db\models\fields\related_descriptors.py", line 513, in __get__
    rel_obj = self.related.get_cached_value(instance)
              ^^^^^^^^^^^^^^^^^^^^^^^^^^^^^^^^^^^^^^^
  File "C:\Users\priya\OneDrive\Documents\IT\python\pd\django_emr\venv\Lib\site-packages\django\db\models\fields\mixins.py", line 37, in get_cached_value
    return instance._state.fields_cache[self.cache_name]
           ~~~~~~~~~~~~~~~~~~~~~~~~~~~~^^^^^^^^^^^^^^^^^
KeyError: 'doctor_profile'

During handling of the above exception, another exception occurred:

Traceback (most recent call last):
  File "C:\Users\priya\OneDrive\Documents\IT\python\pd\django_emr\venv\Lib\site-packages\django\db\backends\utils.py", line 105, in _execute
    return self.cursor.execute(sql, params)
           ^^^^^^^^^^^^^^^^^^^^^^^^^^^^^^^^
  File "C:\Users\priya\OneDrive\Documents\IT\python\pd\django_emr\venv\Lib\site-packages\django\db\backends\mysql\base.py", line 76, in execute
    return self.cursor.execute(query, args)
           ^^^^^^^^^^^^^^^^^^^^^^^^^^^^^^^^
  File "C:\Users\priya\OneDrive\Documents\IT\python\pd\django_emr\venv\Lib\site-packages\MySQLdb\cursors.py", line 179, in execute
    res = self._query(mogrified_query)
          ^^^^^^^^^^^^^^^^^^^^^^^^^^^^
  File "C:\Users\priya\OneDrive\Documents\IT\python\pd\django_emr\venv\Lib\site-packages\MySQLdb\cursors.py", line 330, in _query
    db.query(q)
  File "C:\Users\priya\OneDrive\Documents\IT\python\pd\django_emr\venv\Lib\site-packages\MySQLdb\connections.py", line 280, in query
    _mysql.connection.query(self, query)
MySQLdb.ProgrammingError: (1146, "Table 'emr_db.emr_app_doctor' doesn't exist")

The above exception was the direct cause of the following exception:

Traceback (most recent call last):
  File "C:\Users\priya\OneDrive\Documents\IT\python\pd\django_emr\venv\Lib\site-packages\django\core\handlers\exception.py", line 55, in inner
    response = get_response(request)
               ^^^^^^^^^^^^^^^^^^^^^
  File "C:\Users\priya\OneDrive\Documents\IT\python\pd\django_emr\venv\Lib\site-packages\django\core\handlers\base.py", line 197, in _get_response
    response = wrapped_callback(request, *callback_args, **callback_kwargs)
               ^^^^^^^^^^^^^^^^^^^^^^^^^^^^^^^^^^^^^^^^^^^^^^^^^^^^^^^^^^^^
  File "C:\Users\priya\OneDrive\Documents\IT\python\pd\django_emr\venv\Lib\site-packages\django\contrib\auth\decorators.py", line 59, in _view_wrapper
    return view_func(request, *args, **kwargs)
           ^^^^^^^^^^^^^^^^^^^^^^^^^^^^^^^^^^^
  File "C:\Users\priya\OneDrive\Documents\IT\python\pd\django_emr\emr_project\emr_app\views.py", line 107, in home
    if request.user.is_staff or is_doctor(request.user):
                                ^^^^^^^^^^^^^^^^^^^^^^^
  File "C:\Users\priya\OneDrive\Documents\IT\python\pd\django_emr\emr_project\emr_app\views.py", line 39, in is_doctor
    return hasattr(user, 'doctor_profile') and user.doctor_profile.is_active
           ^^^^^^^^^^^^^^^^^^^^^^^^^^^^^^^
  File "C:\Users\priya\OneDrive\Documents\IT\python\pd\django_emr\venv\Lib\site-packages\django\utils\functional.py", line 253, in inner
    return func(_wrapped, *args)
           ^^^^^^^^^^^^^^^^^^^^^
  File "C:\Users\priya\OneDrive\Documents\IT\python\pd\django_emr\venv\Lib\site-packages\django\db\models\fields\related_descriptors.py", line 520, in __get__
    rel_obj = self.get_queryset(instance=instance).get(**filter_args)
              ^^^^^^^^^^^^^^^^^^^^^^^^^^^^^^^^^^^^^^^^^^^^^^^^^^^^^^^
  File "C:\Users\priya\OneDrive\Documents\IT\python\pd\django_emr\venv\Lib\site-packages\django\db\models\query.py", line 629, in get
    num = len(clone)
          ^^^^^^^^^^
  File "C:\Users\priya\OneDrive\Documents\IT\python\pd\django_emr\venv\Lib\site-packages\django\db\models\query.py", line 366, in __len__
    self._fetch_all()
  File "C:\Users\priya\OneDrive\Documents\IT\python\pd\django_emr\venv\Lib\site-packages\django\db\models\query.py", line 1935, in _fetch_all
    self._result_cache = list(self._iterable_class(self))
                         ^^^^^^^^^^^^^^^^^^^^^^^^^^^^^^^^
  File "C:\Users\priya\OneDrive\Documents\IT\python\pd\django_emr\venv\Lib\site-packages\django\db\models\query.py", line 91, in __iter__
    results = compiler.execute_sql(
              ^^^^^^^^^^^^^^^^^^^^^
  File "C:\Users\priya\OneDrive\Documents\IT\python\pd\django_emr\venv\Lib\site-packages\django\db\models\sql\compiler.py", line 1622, in execute_sql
    cursor.execute(sql, params)
  File "C:\Users\priya\OneDrive\Documents\IT\python\pd\django_emr\venv\Lib\site-packages\django\db\backends\utils.py", line 122, in execute
    return super().execute(sql, params)
           ^^^^^^^^^^^^^^^^^^^^^^^^^^^^
  File "C:\Users\priya\OneDrive\Documents\IT\python\pd\django_emr\venv\Lib\site-packages\django\db\backends\utils.py", line 79, in execute
    return self._execute_with_wrappers(
           ^^^^^^^^^^^^^^^^^^^^^^^^^^^^
  File "C:\Users\priya\OneDrive\Documents\IT\python\pd\django_emr\venv\Lib\site-packages\django\db\backends\utils.py", line 92, in _execute_with_wrappers
    return executor(sql, params, many, context)
           ^^^^^^^^^^^^^^^^^^^^^^^^^^^^^^^^^^^^
  File "C:\Users\priya\OneDrive\Documents\IT\python\pd\django_emr\venv\Lib\site-packages\django\db\backends\utils.py", line 100, in _execute
    with self.db.wrap_database_errors:
         ^^^^^^^^^^^^^^^^^^^^^^^^^^^^
  File "C:\Users\priya\OneDrive\Documents\IT\python\pd\django_emr\venv\Lib\site-packages\django\db\utils.py", line 91, in __exit__
    raise dj_exc_value.with_traceback(traceback) from exc_value
  File "C:\Users\priya\OneDrive\Documents\IT\python\pd\django_emr\venv\Lib\site-packages\django\db\backends\utils.py", line 105, in _execute
    return self.cursor.execute(sql, params)
           ^^^^^^^^^^^^^^^^^^^^^^^^^^^^^^^^
  File "C:\Users\priya\OneDrive\Documents\IT\python\pd\django_emr\venv\Lib\site-packages\django\db\backends\mysql\base.py", line 76, in execute
    return self.cursor.execute(query, args)
           ^^^^^^^^^^^^^^^^^^^^^^^^^^^^^^^^
  File "C:\Users\priya\OneDrive\Documents\IT\python\pd\django_emr\venv\Lib\site-packages\MySQLdb\cursors.py", line 179, in execute
    res = self._query(mogrified_query)
          ^^^^^^^^^^^^^^^^^^^^^^^^^^^^
  File "C:\Users\priya\OneDrive\Documents\IT\python\pd\django_emr\venv\Lib\site-packages\MySQLdb\cursors.py", line 330, in _query
    db.query(q)
  File "C:\Users\priya\OneDrive\Documents\IT\python\pd\django_emr\venv\Lib\site-packages\MySQLdb\connections.py", line 280, in query
    _mysql.connection.query(self, query)
django.db.utils.ProgrammingError: (1146, "Table 'emr_db.emr_app_doctor' doesn't exist")
ERROR 2025-08-04 14:52:01,871 basehttp 18516 11580 "GET / HTTP/1.1" 500 211912
INFO 2025-08-04 15:12:35,611 autoreload 5132 22064 Watching for file changes with StatReloader
ERROR 2025-08-04 15:12:52,801 log 5132 7620 Internal Server Error: /
Traceback (most recent call last):
  File "C:\Users\priya\AppData\Local\Packages\PythonSoftwareFoundation.Python.3.12_qbz5n2kfra8p0\LocalCache\local-packages\Python312\site-packages\django\db\models\fields\related_descriptors.py", line 473, in __get__
    rel_obj = self.related.get_cached_value(instance)
              ^^^^^^^^^^^^^^^^^^^^^^^^^^^^^^^^^^^^^^^
  File "C:\Users\priya\AppData\Local\Packages\PythonSoftwareFoundation.Python.3.12_qbz5n2kfra8p0\LocalCache\local-packages\Python312\site-packages\django\db\models\fields\mixins.py", line 15, in get_cached_value
    return instance._state.fields_cache[cache_name]
           ~~~~~~~~~~~~~~~~~~~~~~~~~~~~^^^^^^^^^^^^
KeyError: 'doctor_profile'

During handling of the above exception, another exception occurred:

Traceback (most recent call last):
  File "C:\Users\priya\AppData\Local\Packages\PythonSoftwareFoundation.Python.3.12_qbz5n2kfra8p0\LocalCache\local-packages\Python312\site-packages\django\db\backends\utils.py", line 89, in _execute
    return self.cursor.execute(sql, params)
           ^^^^^^^^^^^^^^^^^^^^^^^^^^^^^^^^
  File "C:\Users\priya\AppData\Local\Packages\PythonSoftwareFoundation.Python.3.12_qbz5n2kfra8p0\LocalCache\local-packages\Python312\site-packages\django\db\backends\mysql\base.py", line 75, in execute
    return self.cursor.execute(query, args)
           ^^^^^^^^^^^^^^^^^^^^^^^^^^^^^^^^
  File "C:\Users\priya\AppData\Local\Packages\PythonSoftwareFoundation.Python.3.12_qbz5n2kfra8p0\LocalCache\local-packages\Python312\site-packages\MySQLdb\cursors.py", line 179, in execute
    res = self._query(mogrified_query)
          ^^^^^^^^^^^^^^^^^^^^^^^^^^^^
  File "C:\Users\priya\AppData\Local\Packages\PythonSoftwareFoundation.Python.3.12_qbz5n2kfra8p0\LocalCache\local-packages\Python312\site-packages\MySQLdb\cursors.py", line 330, in _query
    db.query(q)
  File "C:\Users\priya\AppData\Local\Packages\PythonSoftwareFoundation.Python.3.12_qbz5n2kfra8p0\LocalCache\local-packages\Python312\site-packages\MySQLdb\connections.py", line 257, in query
    _mysql.connection.query(self, query)
MySQLdb.ProgrammingError: (1146, "Table 'emr_db.emr_app_doctor' doesn't exist")

The above exception was the direct cause of the following exception:

Traceback (most recent call last):
  File "C:\Users\priya\AppData\Local\Packages\PythonSoftwareFoundation.Python.3.12_qbz5n2kfra8p0\LocalCache\local-packages\Python312\site-packages\django\core\handlers\exception.py", line 55, in inner
    response = get_response(request)
               ^^^^^^^^^^^^^^^^^^^^^
  File "C:\Users\priya\AppData\Local\Packages\PythonSoftwareFoundation.Python.3.12_qbz5n2kfra8p0\LocalCache\local-packages\Python312\site-packages\django\core\handlers\base.py", line 197, in _get_response
    response = wrapped_callback(request, *callback_args, **callback_kwargs)
               ^^^^^^^^^^^^^^^^^^^^^^^^^^^^^^^^^^^^^^^^^^^^^^^^^^^^^^^^^^^^
  File "C:\Users\priya\AppData\Local\Packages\PythonSoftwareFoundation.Python.3.12_qbz5n2kfra8p0\LocalCache\local-packages\Python312\site-packages\django\contrib\auth\decorators.py", line 23, in _wrapper_view
    return view_func(request, *args, **kwargs)
           ^^^^^^^^^^^^^^^^^^^^^^^^^^^^^^^^^^^
  File "C:\Users\priya\OneDrive\Documents\IT\python\pd\django_emr\emr_project\emr_app\views.py", line 107, in home
    if request.user.is_staff or is_doctor(request.user):
                                ^^^^^^^^^^^^^^^^^^^^^^^
  File "C:\Users\priya\OneDrive\Documents\IT\python\pd\django_emr\emr_project\emr_app\views.py", line 39, in is_doctor
    return hasattr(user, 'doctor_profile') and user.doctor_profile.is_active
           ^^^^^^^^^^^^^^^^^^^^^^^^^^^^^^^
  File "C:\Users\priya\AppData\Local\Packages\PythonSoftwareFoundation.Python.3.12_qbz5n2kfra8p0\LocalCache\local-packages\Python312\site-packages\django\utils\functional.py", line 268, in inner
    return func(_wrapped, *args)
           ^^^^^^^^^^^^^^^^^^^^^
  File "C:\Users\priya\AppData\Local\Packages\PythonSoftwareFoundation.Python.3.12_qbz5n2kfra8p0\LocalCache\local-packages\Python312\site-packages\django\db\models\fields\related_descriptors.py", line 481, in __get__
    rel_obj = self.get_queryset(instance=instance).get(**filter_args)
              ^^^^^^^^^^^^^^^^^^^^^^^^^^^^^^^^^^^^^^^^^^^^^^^^^^^^^^^
  File "C:\Users\priya\AppData\Local\Packages\PythonSoftwareFoundation.Python.3.12_qbz5n2kfra8p0\LocalCache\local-packages\Python312\site-packages\django\db\models\query.py", line 633, in get
    num = len(clone)
          ^^^^^^^^^^
  File "C:\Users\priya\AppData\Local\Packages\PythonSoftwareFoundation.Python.3.12_qbz5n2kfra8p0\LocalCache\local-packages\Python312\site-packages\django\db\models\query.py", line 380, in __len__
    self._fetch_all()
  File "C:\Users\priya\AppData\Local\Packages\PythonSoftwareFoundation.Python.3.12_qbz5n2kfra8p0\LocalCache\local-packages\Python312\site-packages\django\db\models\query.py", line 1881, in _fetch_all
    self._result_cache = list(self._iterable_class(self))
                         ^^^^^^^^^^^^^^^^^^^^^^^^^^^^^^^^
  File "C:\Users\priya\AppData\Local\Packages\PythonSoftwareFoundation.Python.3.12_qbz5n2kfra8p0\LocalCache\local-packages\Python312\site-packages\django\db\models\query.py", line 91, in __iter__
    results = compiler.execute_sql(
              ^^^^^^^^^^^^^^^^^^^^^
  File "C:\Users\priya\AppData\Local\Packages\PythonSoftwareFoundation.Python.3.12_qbz5n2kfra8p0\LocalCache\local-packages\Python312\site-packages\django\db\models\sql\compiler.py", line 1562, in execute_sql
    cursor.execute(sql, params)
  File "C:\Users\priya\AppData\Local\Packages\PythonSoftwareFoundation.Python.3.12_qbz5n2kfra8p0\LocalCache\local-packages\Python312\site-packages\django\db\backends\utils.py", line 102, in execute
    return super().execute(sql, params)
           ^^^^^^^^^^^^^^^^^^^^^^^^^^^^
  File "C:\Users\priya\AppData\Local\Packages\PythonSoftwareFoundation.Python.3.12_qbz5n2kfra8p0\LocalCache\local-packages\Python312\site-packages\django\db\backends\utils.py", line 67, in execute
    return self._execute_with_wrappers(
           ^^^^^^^^^^^^^^^^^^^^^^^^^^^^
  File "C:\Users\priya\AppData\Local\Packages\PythonSoftwareFoundation.Python.3.12_qbz5n2kfra8p0\LocalCache\local-packages\Python312\site-packages\django\db\backends\utils.py", line 80, in _execute_with_wrappers
    return executor(sql, params, many, context)
           ^^^^^^^^^^^^^^^^^^^^^^^^^^^^^^^^^^^^
  File "C:\Users\priya\AppData\Local\Packages\PythonSoftwareFoundation.Python.3.12_qbz5n2kfra8p0\LocalCache\local-packages\Python312\site-packages\django\db\backends\utils.py", line 84, in _execute
    with self.db.wrap_database_errors:
         ^^^^^^^^^^^^^^^^^^^^^^^^^^^^
  File "C:\Users\priya\AppData\Local\Packages\PythonSoftwareFoundation.Python.3.12_qbz5n2kfra8p0\LocalCache\local-packages\Python312\site-packages\django\db\utils.py", line 91, in __exit__
    raise dj_exc_value.with_traceback(traceback) from exc_value
  File "C:\Users\priya\AppData\Local\Packages\PythonSoftwareFoundation.Python.3.12_qbz5n2kfra8p0\LocalCache\local-packages\Python312\site-packages\django\db\backends\utils.py", line 89, in _execute
    return self.cursor.execute(sql, params)
           ^^^^^^^^^^^^^^^^^^^^^^^^^^^^^^^^
  File "C:\Users\priya\AppData\Local\Packages\PythonSoftwareFoundation.Python.3.12_qbz5n2kfra8p0\LocalCache\local-packages\Python312\site-packages\django\db\backends\mysql\base.py", line 75, in execute
    return self.cursor.execute(query, args)
           ^^^^^^^^^^^^^^^^^^^^^^^^^^^^^^^^
  File "C:\Users\priya\AppData\Local\Packages\PythonSoftwareFoundation.Python.3.12_qbz5n2kfra8p0\LocalCache\local-packages\Python312\site-packages\MySQLdb\cursors.py", line 179, in execute
    res = self._query(mogrified_query)
          ^^^^^^^^^^^^^^^^^^^^^^^^^^^^
  File "C:\Users\priya\AppData\Local\Packages\PythonSoftwareFoundation.Python.3.12_qbz5n2kfra8p0\LocalCache\local-packages\Python312\site-packages\MySQLdb\cursors.py", line 330, in _query
    db.query(q)
  File "C:\Users\priya\AppData\Local\Packages\PythonSoftwareFoundation.Python.3.12_qbz5n2kfra8p0\LocalCache\local-packages\Python312\site-packages\MySQLdb\connections.py", line 257, in query
    _mysql.connection.query(self, query)
django.db.utils.ProgrammingError: (1146, "Table 'emr_db.emr_app_doctor' doesn't exist")
ERROR 2025-08-04 15:12:52,831 basehttp 5132 7620 "GET / HTTP/1.1" 500 213992
INFO 2025-08-04 15:21:30,336 autoreload 17456 7332 Watching for file changes with StatReloader
INFO 2025-08-04 15:21:35,244 basehttp 17456 16868 "GET / HTTP/1.1" 302 0
INFO 2025-08-04 15:21:35,486 basehttp 17456 16868 "GET /login/?next=/ HTTP/1.1" 200 13693
INFO 2025-08-04 15:21:38,003 basehttp 17456 16868 "POST /login/?next=/ HTTP/1.1" 200 13852
INFO 2025-08-04 15:21:45,597 basehttp 17456 16868 "GET /signup/ HTTP/1.1" 200 15161
INFO 2025-08-04 15:22:34,615 basehttp 17456 16868 "POST /signup/ HTTP/1.1" 200 15743
INFO 2025-08-04 15:23:00,456 basehttp 17456 16868 "POST /signup/ HTTP/1.1" 200 15743
INFO 2025-08-04 15:24:04,494 basehttp 17456 16868 "POST /signup/ HTTP/1.1" 302 0
INFO 2025-08-04 15:24:04,592 basehttp 17456 16868 "GET / HTTP/1.1" 200 22604
INFO 2025-08-04 15:24:15,098 basehttp 17456 16868 "GET /patients/ HTTP/1.1" 200 20488
INFO 2025-08-04 15:24:19,811 basehttp 17456 16868 "GET /checkups/ HTTP/1.1" 200 646
INFO 2025-08-04 15:24:23,294 basehttp 17456 16868 "GET / HTTP/1.1" 200 22170
INFO 2025-08-04 15:24:37,415 basehttp 17456 16868 "GET /admin/login/?next=/admin/ HTTP/1.1" 200 3715
INFO 2025-08-04 15:24:37,639 basehttp 17456 16868 "GET /static/admin/css/login.css HTTP/1.1" 200 958
INFO 2025-08-04 15:24:42,635 basehttp 17456 16868 "POST /admin/login/?next=/admin/ HTTP/1.1" 200 3884
INFO 2025-08-04 15:27:24,141 basehttp 17456 16868 "GET / HTTP/1.1" 302 0
INFO 2025-08-04 15:27:24,191 basehttp 17456 16868 "GET /login/?next=/ HTTP/1.1" 200 13693
INFO 2025-08-04 15:27:29,998 basehttp 17456 16868 "GET /login/?next=/admin HTTP/1.1" 200 13693
INFO 2025-08-04 15:27:36,188 basehttp 17456 16868 "GET /admin/login/?next=/admin/ HTTP/1.1" 200 4188
INFO 2025-08-04 15:27:36,255 basehttp 17456 16868 "GET /static/admin/css/login.css HTTP/1.1" 304 0
INFO 2025-08-04 15:27:53,102 basehttp 17456 16868 "POST /admin/login/?next=/admin/ HTTP/1.1" 302 0
INFO 2025-08-04 15:27:53,204 basehttp 17456 16868 "GET /admin/ HTTP/1.1" 200 10280
INFO 2025-08-04 15:28:00,874 basehttp 17456 16868 "GET /admin/auth/user/ HTTP/1.1" 200 14531
INFO 2025-08-04 15:28:00,989 basehttp 17456 16868 "GET /admin/jsi18n/ HTTP/1.1" 200 3343
INFO 2025-08-04 15:28:13,945 basehttp 17456 16868 "GET / HTTP/1.1" 200 22170
INFO 2025-08-04 15:38:34,880 autoreload 17456 7332 C:\Users\priya\OneDrive\Documents\IT\python\pd\django_emr\emr_project\emr_app\urls.py changed, reloading.
INFO 2025-08-04 15:38:36,800 autoreload 16724 16344 Watching for file changes with StatReloader
INFO 2025-08-04 15:38:53,368 autoreload 16724 16344 C:\Users\priya\OneDrive\Documents\IT\python\pd\django_emr\emr_project\emr_app\views.py changed, reloading.
INFO 2025-08-04 15:38:55,228 autoreload 22820 14360 Watching for file changes with StatReloader
INFO 2025-08-04 15:42:02,764 autoreload 22984 15920 Watching for file changes with StatReloader
INFO 2025-08-04 15:42:08,948 basehttp 22820 16536 "GET / HTTP/1.1" 200 32368
INFO 2025-08-04 15:42:37,248 basehttp 22820 16536 "GET /login/ HTTP/1.1" 200 13693
INFO 2025-08-04 15:46:29,645 basehttp 22820 16536 "GET /login/ HTTP/1.1" 200 32379
INFO 2025-08-04 16:23:06,291 autoreload 6192 23144 Watching for file changes with StatReloader
INFO 2025-08-05 10:14:43,667 basehttp 6192 23580 "GET /login/ HTTP/1.1" 200 32379
INFO 2025-08-06 13:39:06,894 autoreload 11392 14208 Watching for file changes with StatReloader
INFO 2025-08-06 13:39:20,195 basehttp 11392 26348 "GET / HTTP/1.1" 200 32368
INFO 2025-08-06 13:39:26,924 basehttp 11392 26348 "GET /login/ HTTP/1.1" 200 32379
INFO 2025-08-06 13:39:57,439 basehttp 11392 26348 "GET /signup/ HTTP/1.1" 200 15161
INFO 2025-08-06 13:40:27,323 basehttp 11392 26348 "POST /signup/ HTTP/1.1" 200 15752
INFO 2025-08-06 13:40:47,492 basehttp 11392 26348 "POST /signup/ HTTP/1.1" 302 0
INFO 2025-08-06 13:40:47,620 basehttp 11392 26348 "GET /dashboard/ HTTP/1.1" 200 34466
